Workbook
Name chuong_phuluc_48: '48'!$D$1
Name chuong_phuluc_48_name: '48'!$A$2
Name chuong_phuluc_50: '50'!#REF!
Name chuong_phuluc_50_name: '50'!$A$2
Name chuong_phuluc_51: '51'!$D$1
Name chuong_phuluc_51_name: '51'!$A$2
Name chuong_phuluc_52: '52'!$F$1
Name chuong_phuluc_52_name: '52'!$A$2
Name chuong_phuluc_53: '53'!$K$1
Name chuong_phuluc_53_name: '53'!$A$2
Name chuong_phuluc_54: '54'!#REF!
Name chuong_phuluc_54_name: '54'!$A$2
Name chuong_phuluc_55: '54'!#REF!
Name chuong_phuluc_55_name: '54'!#REF!
Name chuong_phuluc_58: '58'!$AB$1
Name chuong_phuluc_58_name: '58'!$A$2
Name chuong_phuluc_59: '59'!$Z$1
Name chuong_phuluc_59_name: '59'!$A$2
Name tvpllink_orzgiqxtpn_27: '51'!$A$33
Name tvpllink_orzgiqxtpn_28: '52'!$A$47
Name tvpllink_orzgiqxtpn_29: '53'!$A$36
Name tvpllink_orzgiqxtpn_30: '54'!#REF!

Sheet foxz

Sheet 48
D1: Biểu mẫu số 48 Kèm theo Nghị định 31/2017/NĐ-CP ngày 23/3/2017 của Chính Phủ
A2: QUYẾT TOÁN CÂN ĐỐI NGÂN SÁCH ĐỊA PHƯƠNG NĂM 2025
A3: (Kèm theo Nghị quyết số 09 /NQ-HĐND ngày 30 tháng 3 năm 2026 của HĐND xã Quang Sơn)
E4: ĐVT: triệu đồng
A5: STT | B5: Nội dung (1) | C5: Dự toán | D5: Quyết toán | E5: So Sánh
E6: Tuyệt đối | F6: Tương đối (%)
A7: A | B7: B | C7: 1 | D7: 2 | E7: 3=2-1 | F7: 4=2/1
A8: A | B8: TỔNG NGUỒN THU NSĐP | C8: =+C9+C12+C16+C17+C18+C19 -> 124134 | D8: =+D9+D12+D17+D18 -> 144925 | E8: =+D8-C8 -> 20791 | F8: =+D8/C8 -> 1.1674884
A9: I | B9: Thu NSĐP được hưởng theo phân cấp | C9: 0 | D9: 180 | E9: =+D9-C9 -> 180
A10: 1 | B10: Các khoản thu NSĐP hưởng 100% | C10: 0 | D10: 180.19857 | E10: =+D10-C10 -> 180.19857
A11: 2 | B11: Thu NSĐP hưởng từ các khoản thu phân chia | C11: 0 | D11: 0 | E11: 0
A12: II | B12: Thu bổ sung từ ngân sách cấp trên | C12: =+C13+C14+C15 -> 110863 | D12: =+D13+D15 -> 142247 | E12: =+D12-C12 -> 31384 | F12: =+D12/C12 -> 1.2830881
A13: - | B13: Thu bổ sung cân đối ngân sách | C13: 14866 | D13: 14866 | E13: =+D13-C13 -> 0 | F13: =+D13/C13 -> 1
A14: - | B14: Thu TC bổ sung thực hiện cải cách tiền lương | C14: 0 | D14: 0 | E14: 0
A15: - | B15: Thu bổ sung có mục tiêu | C15: 95997 | D15: 127381 | E15: =+D15-C15 -> 31384 | F15: =+D15/C15 -> 1.3269269
A16: III | B16: Thu từ các khoản cho vay của nhà nước và thu từ quỹ dự trữ tài chính | C16: 0 | D16: 0 | E16: 0
A17: IV | B17: Thu kết dư | C17: 4868 | D17: 376 | E17: =+D17-C17 -> -4492 | F17: =+D17/C17 -> 0.077239113
A18: V | B18: Thu chuyển nguồn từ năm trước chuyển sang | C18: 5281 | D18: 2122 | E18: =+D18-C18 -> -3159 | F18: =+D18/C18 -> 0.40181784
A19: VI | B19: Các khoản huy động, đóng góp | C19: 3122 | D19: 0 | E19: 0
A20: B | B20: TỔNG CHI NSĐP | C20: =+C21+C28+C31+C32+C33+C34+C35 -> 124134 | D20: =+D21+D31+D28+D36+D37+D40+D43+D32 -> 138427 | E20: =+D20-C20 -> 14293 | F20: =+D20/C20 -> 1.1151417
A21: I | B21: Tổng chi cân đối NSĐP | C21: =+C22+C23+C24+C25+C26+C27 -> 93325 | D21: 102911 | E21: =+D21-C21 -> 9586 | F21: =+D21/C21 -> 1.1027163 | G21: =+D21-'51'!D8 -> 0
A22: 1 | B22: Chi đầu tư phát triển | C22: 2683 | D22: 5686 | E22: =+D22-C22 -> 3003 | F22: =+D22/C22 -> 2.1192695 | G22: =+C8-C20 -> 0
A23: 2 | B23: Chi thường xuyên | C23: 88821 | D23: 97225 | E23: =+D23-C23 -> 8404 | F23: =+D23/C23 -> 1.0946173
A24: 3 | B24: Chi trả nợ lãi các khoản do chính quyền địa phương vay | C24: 0 | D24: 0 | E24: 0
A25: 4 | B25: Chi bổ sung quỹ dự trữ tài chính | C25: 0 | D25: 0 | E25: 0
A26: 5 | B26: Chi tạo nguồn, điều chỉnh tiền lương | C26: 0 | D26: 0 | E26: 0
A27: 6 | B27: Dự phòng ngân sách | C27: 1821 | D27: 0 | E27: 0
A28: II | B28: Chi các chương trình mục tiêu | C28: =+C29+C30 -> 17538 | D28: 21141 | E28: =+D28-C28 -> 3603 | F28: =+D28/C28 -> 1.2054396
A29: 1 | B29: Chi các chương trình mục tiêu quốc gia | C29: 17303 | D29: 21141 | E29: =+D29-C29 -> 3838 | F29: =+D29/C29 -> 1.2218112
A30: 2 | B30: Chi các chương trình mục tiêu, nhiệm vụ | C30: 235
A31: III | B31: Chi chuyển nguồn năm sau | C31: 0 | D31: 14300 | E31: 143030
A32: IV | B32: Chi nộp ngân sách cấp trên | C32: 0 | D32: 75 | E32: 75
A33: V | B33: Chi từ nguồn kết dư | C33: 4868 | D33: 0 | E33: 0
A34: VI | B34: Chi từ nguồn chuyển nguồn | C34: 5281
A35: VII | B35: Chi từ nguồn viện trợ, huy động, đóng góp | C35: 3122
A36: C | B36: BỘI CHI NSĐP/BỘI THU NSĐP/KẾT DƯ NSĐP | C36: 0 | D36: 0 | E36: 0
A37: D | B37: CHI TRẢ NỢ GỐC CỦA NSĐP | C37: 0 | D37: 0 | E37: 0
A38: I | B38: Từ nguồn vay để trả nợ gốc | C38: 0 | D38: 0 | E38: 0
A39: II | B39: Từ nguồn bội thu, tăng thu, tiết kiệm chi, kết dư ngân sách cấp tỉnh | C39: 0 | D39: 0 | E39: 0
A40: E | B40: TỔNG MỨC VAY CỦA NSĐP | C40: 0 | D40: 0 | E40: 0
...

Sheet 50
F1: Biểu mẫu số 50 Kèm theo Nghị định 31/2017/NĐ-CP ngày 23/3/2017 của Chính Phủ
A2: QUYẾT TOÁN NGUỒN THU NGÂN SÁCH NHÀ NƯỚC TRÊN ĐỊA BÀN THEO LĨNH VỰC NĂM 2025
A3: =+'48'!A3:F3 -> (Kèm theo Nghị quyết số 09 /NQ-HĐND ngày 30 tháng 3 năm 2026 của HĐND xã Quang Sơn)
G4: ĐVT: triệu đồng
A5: STT | B5: NỘI DUNG | C5: Dự toán | E5: Quyết toán | G5: So sánh(%)
C6: NSNN | D6: NSĐP | E6: NSNN | F6: NS XÃ | G6: NSNN | H6: NSĐP
A7: A | B7: B | C7: 1 | D7: 2 | E7: 3 | F7: 4 | G7: 5=3/1 | H7: 6=4/2
B8: TỔNG NGUỒN THU NSNN(A+B+C+D) | C8: =+C9+C53+C54+C55 -> 17729 | D8: =+D9+D53+D54+D55 -> 0 | E8: =+E9+E54+E55 -> 43265 | F8: 2678 | G8: =+E8/C8 -> 2.440352
A9: A | B9: TỔNG THU CÂN ĐỐI NSNN | C9: =+C10+C11+C12+C20+C19+C27+C29+C30+C32+C33+C34+C35+C36+C37+C38+C39+C40+C41 -> 17729 | D9: =+D10+D11+D12+D19+D20 -> 0 | E9: =+E10+E42+E43+E51+E52 -> 40767 | F9: =+F10+F42+F43+F51+F52 -> 180 | G9: =+E9/C9 -> 2.2994529
A10: I | B10: Thu nội địa | C10: 0 | D10: 0 | E10: =+E12+E11+E20+E27+E28+E29+E30+E31+E32+E33+E34+E35+E36+E37+E38 -> 37645 | F10: 180
A11: 1 | B11: Thu từ khu vực DNNN do TW quản lý | C11: 0 | D11: 0 | E11: 0 | F11: 0
A12: 2 | B12: Thu từ khu vực DNNN do địa phương quản lý | C12: 0 | D12: 0 | E12: 25 | F12: 0
A13: - | B13: Thuế giá trị gia tăng | C13: 0 | D13: 0 | E13: 6 | F13: 0
A14: - | B14: Thuế thu nhập doanh nghiệp | C14: 0 | D14: 0 | E14: 19 | F14: 0
A15: - | B15: Thuế tiêu thụ đặc biệt | C15: 0 | D15: 0 | E15: 0 | F15: 0
A16: - | B16: Thuế tài nguyên | C16: 0 | D16: 0 | E16: 0 | F16: 0
A17: - | B17: Thuế môn bài | C17: 0 | D17: 0 | E17: 0 | F17: 0
A18: - | B18: Thu khác | C18: 0 | D18: 0 | E18: 0 | F18: 0
A19: 3 | B19: Thu từ khu vực doanh nghiệp có vốn đầu tư nước ngoài | C19: 0 | D19: 0 | E19: 0 | F19: 0
A20: 4 | B20: Thu từ khu vực kinh tế ngoài quốc doanh | C20: 6019 | E20: 28651 | F20: 0 | G20: =+E20/C20 -> 4.760093
A21: - | B21: Thuế giá trị gia tăng | C21: 0 | E21: 26096 | F21: 0
A22: - | B22: Thuế thu nhập doanh nghiệp | C22: 0 | E22: 939 | F22: 0
A23: - | B23: Thuế tiêu thụ đặc biệt | C23: 0 | E23: 0 | F23: 0
A24: - | B24: Thuế tài nguyên | C24: 0 | E24: 1616 | F24: 0
A25: - | B25: Thuế môn bài | C25: 0 | E25: 0 | F25: 0
A26: - | B26: Thu khác | C26: 0 | E26: 0 | F26: 0
A27: 5 | B27: Thuế thu nhập cá nhân | C27: 398 | E27: 384 | F27: 0 | G27: =+E27/C27 -> 0.96482412
A28: 6 | B28: Thuế bảo vệ môi trường | C28: 0 | E28: 0 | F28: 0
A29: 7 | B29: Lệ phí trước bạ | C29: 1456 | E29: 2882 | F29: 0 | G29: =+E29/C29 -> 1.9793956
A30: 8 | B30: Phí, lệ phí | C30: 1303 | E30: 929 | F30: 0 | G30: =+E30/C30 -> 0.71297007
A31: 9 | B31: Thuế sử dụng đất nông nghiệp | C31: 0 | E31: 0 | F31: 0
A32: 10 | B32: Thuế sử dụng đất phi nông nghiệp | C32: 30 | E32: 61 | F32: 0 | G32: =+E32/C32 -> 2.0333333
A33: 11 | B33: Tiền cho thuê đất, thuê mặt nước | C33: 5192 | E33: 1309 | F33: 0 | G33: =+E33/C33 -> 0.25211864
A34: 12 | B34: Tiền sử dụng đất | C34: 210 | E34: 408 | F34: 0 | G34: =+E34/C34 -> 1.9428571
A35: 13 | B35: Tiền cho thuê và bán nhà thuộc sở hữu nhà nước | C35: 0 | E35: 0 | F35: 0
A36: 14 | B36: Thu từ hoạt động xổ số kiến thiết | C36: 0 | E36: 0 | F36: 0
A37: 15 | B37: Thu tiền cấp quyền khai thác khoáng sản, vùng trời, vùng biển | C37: 1901 | E37: 2165 | F37: 0 | G37: =+E37/C37 -> 1.1388743
A38: 16 | B38: Thu khác ngân sách | C38: 1220 | E38: 831 | F38: 180 | G38: =+E38/C38 -> 0.68114754 | I38: 639700000
A39: 17 | B39: Thu từ quỹ đất công ích và thu hoa lợi công sản khác | C39: 0 | E39: 0 | F39: 0
A40: 18 | B40: Thu hồi vốn, thu cổ tức | C40: 0 | E40: 0 | F40: 0
...

Sheet 51
D1: Biểu mẫu số 51 Kèm theo Nghị định 31/2017/NĐ-CP ngày 23/3/2017 của Chính Phủ
A2: QUYẾT TOÁN CHI NGÂN SÁCH ĐỊA PHƯƠNG THEO LĨNH VỰC NĂM 2025
A3: =+'48'!A3:F3 -> (Kèm theo Nghị quyết số 09 /NQ-HĐND ngày 30 tháng 3 năm 2026 của HĐND xã Quang Sơn)
E4: Đơn vị: triệu đồng
A5: STT | B5: NỘI DUNG (1) | C5: Dự toán | D5: Quyết toán | E5: So sánh (%)
A6: A | B6: B | C6: 1 | D6: 2 | E6: 3=2/1 | F6: =+D7-'48'!D20 -> 0
B7: TỔNG CHI NGÂN SÁCH ĐỊA PHƯƠNG (không tính chi trả nợ gốc tiền vay) | C7: =+C8+C45+C49+C50+C31+C46+C47+C48 -> 124132 | D7: =+D8+D31+D50+D49+D45 -> 138427 | E7: =+D7/C7 -> 1.1151597 | F7: =+C7-#REF! -> #REF!
A8: A | B8: CHI CÂN ĐỐI NSĐP | C8: =+C9+C23+C27+C28+C29+C30 -> 93325 | D8: 102911 | E8: =+D8/C8 -> 1.1027163 | F8: =+D8-'52'!D10 -> 0
A9: I | B9: Chi đầu tư phát triển | C9: =+C10+C22 -> 2683 | D9: 5686 | E9: =+D9/C9 -> 2.1192695
A10: 1 | B10: Chi đầu tư cho các dự án | C10: =+C12+C13+C14+C15+C17+C16 -> 2683 | D10: 5686 | E10: =+D10/C10 -> 2.1192695
B11: Trong đó: Chia theo lĩnh vực | C11: 0 | D11: 0
A12: - | B12: Chi giáo dục - đào tạo và dạy nghề | C12: 2595 | D12: 5276 | E12: =+D12/C12 -> 2.0331407
A13: - | B13: Chi các hoạt động kinh tế | C13: 86 | D13: 410 | E13: =+D13/C13 -> 4.7674419
A14: - | B14: Chi hoạt động của các cơ quan quản lý nhà nước, Đảng, đoàn thể | C14: 0 | D14: 0
A15: - | B15: Chi văn hoá thông tin | C15: 0 | D15: 0
A16: - | B16: Chi bảo đảm xã hội | C16: 2 | D16: 0 | E16: =+D16/C16 -> 0
A17: - | B17: Chi cho ngân hàng chính sách xã hội | C17: 0 | D17: 0
B18: Trong đó: Chia theo nguồn vốn | C18: 0 | D18: 0
A19: - | B19: Chi đầu tư từ nguồn thu tiền sử dụng đất | C19: 2683 | D19: 2442 | E19: =+D19/C19 -> 0.91017518
A20: - | B20: Chi đầu tư từ nguồn thu xổ số kiến thiết | C20: 0 | D20: 0
A21: - | B21: Chi từ nguồn vốn tập trung ngân sách | C21: 0 | D21: 0
A22: 2 | B22: Chi đầu tư phát triển khác | C22: 0 | D22: 0
A23: II | B23: Chi thường xuyên | C23: 88821 | D23: 97225 | E23: =+D23/C23 -> 1.0946173
B24: Trong đó: | C24: 0 | D24: 0
A25: 1 | B25: Chi giáo dục - đào tạo và dạy nghề | C25: 57971 | D25: 57689 | E25: =+D25/C25 -> 0.9951355
A26: 2 | B26: Chi khoa học và công nghệ | C26: 0 | D26: 0
A27: III | B27: Chi từ nguồn kết dư | C27: 0 | D27: 0
A28: IV | B28: Chi bổ sung quỹ dự trữ tài chính | C28: 0 | D28: 0
A29: V | B29: Dự phòng | C29: 1821 | D29: 0 | E29: =+D29/C29 -> 0
A30: VI | B30: Chi tạo nguồn, điều chỉnh tiền lương | C30: 0 | D30: 0
A31: B | B31: CHI CÁC CHƯƠNG TRÌNH MỤC TIÊU | C31: =+C32+C42 -> 17538 | D31: 21141 | E31: =+D31/C31 -> 1.2054396
A32: I | B32: Chi các chương trình mục tiêu quốc gia | C32: =+C33+C36+C39 -> 17303 | D32: 21141 | E32: =+D32/C32 -> 1.2218112
A33: 1 | B33: Chương trình nông thôn mới | C33: =+C34+C35 -> 6742 | D33: 7689 | E33: =+D33/C33 -> 1.1404628
B34: + Xây dựng cơ bản | C34: 6588 | D34: 7535 | E34: =+D34/C34 -> 1.1437462
B35: +Thường xuyên | C35: 154 | D35: 154 | E35: =+D35/C35 -> 1
A36: 2 | B36: Chương trình giảm nghèo bền vững | C36: =+C37+C38 -> 1040 | D36: 1140 | E36: =+D36/C36 -> 1.0961538
B37: + Xây dựng cơ bản | C37: 0 | D37: 0
B38: +Thường xuyên | C38: 1040 | D38: 1140 | E38: =+D38/C38 -> 1.0961538
A39: 3 | B39: Chương trình phát triển vùng DTTS | C39: =+C40+C41 -> 9521 | D39: 12312 | E39: =+D39/C39 -> 1.2931415
B40: + Xây dựng cơ bản | C40: 5708 | D40: 7904 | E40: =+D40/C40 -> 1.3847232
...

Sheet 52
E1: Biểu mẫu số 52 Kèm theo Nghị định 31/2017/NĐ-CP ngày 23/3/2017 của Chính Phủ
A2: QUYẾT TOÁN CHI NGÂN SÁCH CẤP XÃ THEO LĨNH VỰC NĂM 2025
A3: =+'48'!A3:F3 -> (Kèm theo Nghị quyết số 09 /NQ-HĐND ngày 30 tháng 3 năm 2026 của HĐND xã Quang Sơn)
F4: Đơn vị: triệu đồng
E5: So Sánh
A6: STT | B6: Nội dung | C6: Dự toán | D6: Quyết toán | E6: Tuyệt đối | F6: Tương đối (%)
A7: A | B7: B | C7: 1 | D7: 2 | E7: 3=2-1 | F7: 4=2/1
B8: TỔNG CHI NGÂN SÁCH CẤP TỈNH (không tính chi bổ sung có mục tiêu cho NS cấp dưới và chi trả nợ gốc tiền vay | C8: =+C10+C48+C49+C50+C51 -> 124134 | D8: =+D10+D9+D46+D47+D48+D49+D50+D51 -> 138427 | E8: =+D8-C8 -> 14293 | F8: =+D8/C8 -> 1.1151417 | G8: =+C8-'48'!C20 -> 0
A9: A | B9: CHI BỔ SUNG CHO NGÂN SÁCH CẤP DƯỚI | D9: 0 | E9: =+D9-C9 -> 0
A10: B | B10: CHI NGÂN SÁCH CẤP TỈNH THEO LĨNH VỰC | C10: =+C11+C28+C42+C43+C44+C45 -> 93325 | D10: =+D11+D28+D42+D43+D44+D45 -> 102911 | E10: =+D10-C10 -> 9586 | F10: =+D10/C10 -> 1.1027163
A11: I | B11: Chi đầu tư phát triển | C11: =+C12+C26+C27 -> 2683 | D11: 5686 | E11: =+D11-C11 -> 3003 | F11: =+D11/C11 -> 2.1192695
A12: 1 | B12: Chi đầu tư cho các dự án | C12: =+SUM(C13:C25) -> 2683 | D12: 5686 | E12: =+D12-C12 -> 3003 | F12: =+D12/C12 -> 2.1192695 | G12: 102926493119
A13: - | B13: Chi quốc phòng | C13: 0 | D13: 0 | E13: =+D13-C13 -> 0 | G13: =+G12-D10 -> 102926390208
A14: - | B14: Chi an ninh và trật tự, an toàn xã hội | C14: 0 | D14: 0 | E14: =+D14-C14 -> 0
A15: - | B15: Chi giáo dục, đào tạo và dạy nghề | C15: 2595 | D15: 5276 | E15: =+D15-C15 -> 2681 | F15: =+D15/C15 -> 2.0331407
A16: - | B16: Chi khoa học, công nghệ | C16: 0 | E16: =+D16-C16 -> 0
A17: - | B17: Chi y tế, dân số và gia đình | C17: 0 | E17: =+D17-C17 -> 0
A18: - | B18: Chi văn hoá thông tin | C18: 0 | E18: =+D18-C18 -> 0
A19: - | B19: Chi phát thanh, truyền hình, thông tấn | C19: 0 | E19: =+D19-C19 -> 0
A20: - | B20: Chi thể dục thể thao | C20: 0 | E20: =+D20-C20 -> 0
A21: - | B21: Chi bảo vệ môi trường | C21: 0 | D21: 0 | E21: =+D21-C21 -> 0
A22: - | B22: Chi các hoạt động kinh tế | C22: 86 | D22: 410 | E22: =+D22-C22 -> 324 | F22: =+D22/C22 -> 4.7674419
A23: - | B23: Chi hoạt động của các cơ quan quản lý nhà nước, Đảng, đoàn thể | C23: 0 | E23: =+D23-C23 -> 0
A24: - | B24: Chi bảo đảm xã hội | C24: 2 | F24: =+D24/C24 -> 0
A25: - | B25: Chi các lĩnh vực khác theo quy định của pháp luật | C25: 0 | D25: 0 | E25: =+D25-C25 -> 0
A26: 2 | B26: Chi đầu tư và hỗ trợ vốn cho doanh nghiệp cung cấp sản phẩm, dịch vụ công ích do nhà nước đặt hàng; Các tổ chức kinh tế; Các tổ chức tài chính của trung ương và địa phương | C26: 0 | D26: 0 | E26: =+D26-C26 -> 0
A27: 3 | B27: Chi đầu tư phát triển khác theo quy định của pháp luật | C27: 0 | D27: 0 | E27: =+D27-C27 -> 0
A28: II | B28: Chi thường xuyên theo lĩnh vực | C28: =+C29+C30+C31+C32+C34+C33+C35+C36+C38+C39+C40+C41 -> 88821 | D28: =+SUM(D29:D41) -> 97225 | E28: =+D28-C28 -> 8404 | F28: =+D28/C28 -> 1.0946173
A29: - | B29: Chi quốc phòng | C29: 980 | D29: 911 | E29: =+D29-C29 -> -69 | F29: =+D29/C29 -> 0.92959184
A30: - | B30: Chi an ninh và trật tự, an toàn xã hội | C30: 789 | D30: 788 | E30: =+D30-C30 -> -1 | F30: =+D30/C30 -> 0.99873257
A31: - | B31: Chi giáo dục, đào tạo và dạy nghề | C31: 57971 | D31: 57689 | E31: =+D31-C31 -> -282 | F31: =+D31/C31 -> 0.9951355
A32: - | B32: Chi khoa học, công nghệ | C32: 30 | D32: 0 | E32: =+D32-C32 -> -30 | F32: =+D32/C32 -> 0
A33: - | B33: Chi y tế, dân số và gia đình | C33: 508 | D33: 280 | E33: =+D33-C33 -> -228 | F33: =+D33/C33 -> 0.5511811
A34: - | B34: Chi văn hoá thông tin | C34: 248 | D34: 188 | E34: =+D34-C34 -> -60 | F34: =+D34/C34 -> 0.75806452
A35: - | B35: Chi sự nghiệp phát thanh, truyền hình, thông tấn | C35: 136 | D35: 0 | E35: =+D35-C35 -> -136 | F35: =+D35/C35 -> 0
A36: - | B36: Chi thể dục thể thao | C36: 163 | D36: 155 | E36: =+D36-C36 -> -8 | F36: =+D36/C36 -> 0.95092025
A37: - | B37: Chi bảo vệ môi trường | C37: 0 | D37: 0 | E37: =+D37-C37 -> 0
A38: - | B38: Chi các hoạt động kinh tế | C38: 4739 | D38: 6561 | E38: =+D38-C38 -> 1822 | F38: =+D38/C38 -> 1.3844693
A39: - | B39: Chi hoạt động của các cơ quan quản lý nhà nước, Đảng, đoàn thể | C39: 19012 | D39: 27308 | E39: =+D39-C39 -> 8296 | F39: =+D39/C39 -> 1.436356
A40: - | B40: Chi đảm bảo xã hội | C40: 2683 | D40: 3345 | E40: =+D40-C40 -> 662 | F40: =+D40/C40 -> 1.2467387
...

Sheet 53
I1: Biểu mẫu số 53 Kèm theo Nghị định 31/2017/NĐ-CP ngày 23/3/2017 của Chính Phủ
A2: QUYẾT TOÁN CHI NGÂN SÁCH ĐỊA PHƯƠNG, CHI NGÂN SÁCH CẤP TỈNH VÀ CHI NGÂN SÁCH XÃ THEO CƠ CẤU CHI NĂM 2025
A3: =+'48'!A3:F3 -> (Kèm theo Nghị quyết số 09 /NQ-HĐND ngày 30 tháng 3 năm 2026 của HĐND xã Quang Sơn)
K4: Đơn vị: triệu đồng
A5: STT | B5: Nội dung (1) | C5: Dự toán năm 2025 | D5: Bao gồm | F5: Quyết toán | G5: Bao gồm | I5: So sánh (%)
D6: Dự toán tỉnh | E6: Dự toán xã | G6: Ngân sách tỉnh | H6: Ngân sách xã | I6: Ngân sách địa phương | J6: Ngân sách tỉnh | K6: Ngân sách xã
A7: A | B7: B | C7: 1=2+3 | D7: 2 | E7: 3 | F7: 4=5+6 | G7: 5 | H7: 6 | I7: 7=4/1 | J7: 8=5/2 | K7: 9=6/3
B8: TỔNG CHI NGÂN SÁCH ĐỊA PHƯƠNG | C8: =+D8+E8 -> 124134 | D8: 0 | E8: =+E9+E33+E53+E54+E52+E51+E50 -> 124134 | F8: =+G8+H8 -> 138427 | G8: 0 | H8: =+H9+H33+H54+H53+H52 -> 138427 | I8: =+F8/C8 -> 1.1151417 | K8: =+H8/E8 -> 1.1151417
A9: A | B9: CHI NGÂN SÁCH NHÀ NƯỚC | C9: =+D9+E9 -> 93325 | D9: 0 | E9: =+E10+E25+E29+E30+E31+E32 -> 93325 | F9: =+F10+F25 -> 102911 | G9: 0 | H9: 102911 | I9: =+F9/C9 -> 1.1027163 | K9: =+H9/E9 -> 1.1027163
A10: I | B10: Chi đầu tư phát triển | C10: =+D10+E10 -> 2683 | D10: 0 | E10: =+E11+E24 -> 2683 | F10: 5686 | G10: 0 | H10: 5686 | I10: =+F10/C10 -> 2.1192695 | K10: =+H10/E10 -> 2.1192695
A11: 1 | B11: Đầu tư cho các DA theo các lĩnh vực | C11: =+D11+E11 -> 2683 | D11: 0 | E11: =++E13+E14+E15+E16+E17+E18+E20+E22+E23 -> 2683 | F11: =+H11 -> 5686 | G11: 0 | H11: 5686 | I11: =+F11/C11 -> 2.1192695 | K11: =+H11/E11 -> 2.1192695
B12: Trong đó: chia theo lĩnh vực | C12: =+D12+E12 -> 0 | D12: 0 | E12: 0 | F12: =+H12 -> 0 | G12: 0 | H12: 0
B13: -Chi giáo dục, đào tạo và dạy nghề | C13: =+D13+E13 -> 2595 | D13: 0 | E13: 2595 | F13: =+H13 -> 5276 | G13: 0 | H13: 5276 | I13: =+F13/C13 -> 2.0331407 | K13: =+H13/E13 -> 2.0331407
B14: -Chi các hoạt động kinh tế | C14: =+D14+E14 -> 86 | D14: 0 | E14: 86 | F14: =+H14 -> 410 | G14: 0 | H14: 410 | I14: =+F14/C14 -> 4.7674419 | K14: =+H14/E14 -> 4.7674419
B15: -Chi hoạt động của các cơ quan quản lý nhà nước, Đảng, đoàn thể | C15: =+D15+E15 -> 0 | D15: 0 | E15: 0 | F15: 0 | G15: 0 | H15: 0 | M15: =+H25+H36 -> 102926
B16: -Chi văn hoá thông tin | C16: =+D16+E16 -> 0 | D16: 0 | E16: 0 | F16: 0 | G16: 0 | H16: 0
B17: -Chi bảo đảm xã hội | C17: =+D17+E17 -> 2 | D17: 0 | E17: 2 | F17: 0 | G17: 0 | H17: 0
B18: -Chi khoa học, công nghệ | C18: =+D18+E18 -> 0 | D18: 0 | E18: 0 | F18: 0 | G18: 0 | H18: 0
B19: Trong đó: chia theo nguồn vốn | C19: =+D19+E19 -> 0 | D19: 0 | E19: 0 | F19: 0 | G19: 0 | H19: 0
B20: -Chi đầu tư từ nguồn thu tiền sử dụng đất | C20: =+D20+E20 -> 0 | D20: 0 | E20: 0 | F20: =+G20+H20 -> 2442 | G20: 0 | H20: 2442
B21: Trong đó: chi cho Ngân hàng chính sách xã hội V/v KP đáp ứng nhu cầu vốn vay cho người nghèo và các đối tượng chính sách trên địa bàn thị xã | C21: =+D21+E21 -> 0 | D21: 0 | E21: 0 | F21: 0 | G21: 0 | H21: 0
B22: - Chi từ nguồn vốn tập trung NS | C22: =+D22+E22 -> 0 | D22: 0 | E22: 0 | F22: 0 | G22: 0 | H22: 0
B23: -Chi đầu tư từ nguồn thu xổ số kiến thiết | C23: =+D23+E23 -> 0 | D23: 0 | E23: 0 | F23: 0 | G23: 0 | H23: 0
A24: 2 | B24: Chi đầu tư và hỗ trợ vốn cho các doanh nghiệp cung cấp sản phẩm, dịch vụ công ích do Nhà nước đặt hàng, các tổ chức kinh tế, các tổ chức tài chính của địa phương theo quy định của pháp luật | C24: =+D24+E24 -> 0 | D24: 0 | E24: 0 | F24: 0 | G24: 0 | H24: 0
A25: II | B25: Chi thường xuyên | C25: =+D25+E25 -> 88821 | E25: 88821 | F25: 97225 | G25: 0 | H25: 97225 | I25: =+F25/C25 -> 1.0946173 | K25: =+H25/E25 -> 1.0946173
B26: Trong đó: | C26: =+D26+E26 -> 0 | D26: 0 | E26: 0 | F26: 0 | G26: 0 | H26: 0
A27: 1 | B27: Chi giáo dục, đào tạo và dạy nghề | C27: =+D27+E27 -> 57971 | D27: 0 | E27: 57971 | F27: 57689 | G27: 0 | H27: 57689 | I27: =+F27/C27 -> 0.9951355 | K27: =+H27/E27 -> 0.9951355
A28: 2 | B28: Chi khoa học, công nghệ | C28: =+D28+E28 -> 0 | D28: 0 | E28: 0 | F28: 0 | G28: 0 | H28: 0
A29: III | B29: Chi trả nợ lãi các khoản do chính quyền địa phương vay | C29: =+D29+E29 -> 0 | D29: 0 | E29: 0 | F29: 0 | G29: 0 | H29: 0
A30: IV | B30: Chi bổ sung quỹ dự trữ tài chính | C30: =+D30+E30 -> 0 | D30: 0 | E30: 0 | F30: 0 | G30: 0 | H30: 0
A31: V | B31: Dự phòng ngân sách | C31: =+D31+E31 -> 1821 | D31: 0 | E31: 1821 | F31: 0 | G31: 0 | H31: 0
A32: VI | B32: Chi tạo nguồn, điều chỉnh tiền lương | C32: =+D32+E32 -> 0 | D32: 0 | E32: 0 | F32: 0 | G32: 0 | H32: 0
A33: B | B33: CHI CÁC CHƯƠNG TRÌNH MỤC TIÊU | C33: =+D33+E33 -> 17538 | D33: 0 | E33: =+E37+E47 -> 17538 | F33: =+G33+H33 -> 21141 | G33: 0 | H33: 21141 | I33: =+F33/C33 -> 1.2054396 | K33: =+H33/E33 -> 1.2054396
B34: Trong đó: | C34: =+D34+E34 -> 0 | D34: 0 | E34: 0 | F34: 0 | G34: 0 | H34: 0
B35: -Xây dựng cơ bản | C35: =+D35+E35 -> 12296 | D35: 0 | E35: =+E39+E42+E45+E48 -> 12296 | F35: =+G35+H35 -> 15440 | G35: 0 | H35: 15440 | I35: =+F35/C35 -> 1.2556929 | K35: =+H35/E35 -> 1.2556929
B36: -Thường xuyên | C36: =+D36+E36 -> 5242 | D36: 0 | E36: =+E40+E43+E46+E49 -> 5242 | F36: =+G36+H36 -> 5701 | G36: 0 | H36: 5701 | I36: =+F36/C36 -> 1.087562 | K36: =+H36/E36 -> 1.087562
A37: I | B37: Chi các chương trình mục tiêu quốc gia | C37: =+C38+C41+C44 -> 17303 | D37: =+D38+D41+D44 -> 0 | E37: =+E38+E41+E44 -> 17303 | F37: 21141 | G37: 0 | H37: 21141 | I37: =+F37/C37 -> 1.2218112 | K37: =+H37/E37 -> 1.2218112
A38: 1 | B38: Chương trình giảm nghèo | C38: =+D38+E38 -> 1040 | D38: 0 | E38: =+E39+E40 -> 1040 | F38: 1140 | G38: 0 | H38: 1140 | I38: =+F38/C38 -> 1.0961538 | K38: =+H38/E38 -> 1.0961538
B39: Chi Đầu tư XDCB | C39: =+D39+E39 -> 0 | D39: 0 | E39: 0 | F39: 0 | G39: 0 | H39: 0
B40: Chi thường xuyên | C40: =+D40+E40 -> 1040 | D40: 0 | E40: 1040 | F40: 1140 | G40: 0 | H40: 1140 | I40: =+F40/C40 -> 1.0961538 | K40: =+H40/E40 -> 1.0961538
...

Sheet 54
T1: Biểu mẫu số 54 Kèm theo Nghị định 31/2017/NĐ-CP ngày 23/3/2017 của Chính Phủ
A2: QUYẾT TOÁN CHI NGÂN SÁCH CẤP XÃ CHO TỪNG CƠ QUAN, TỔ CHỨC THEO LĨNH VỰC NĂM 2025
A3: =+'48'!A3:F3 -> (Kèm theo Nghị quyết số 09 /NQ-HĐND ngày 30 tháng 3 năm 2026 của HĐND xã Quang Sơn)
U4: Đơn vị: Triệu đồng
A5: STT | B5: Tên đơn vị | C5: Dự toán 2025 | J5: Quyết toán 2025 | T5: So sánh
C6: Tổng cộng Dự toán | D6: Chi ĐT phát triển (không kể CTMTQG) | E6: Chi TX (không kể CTMTQG) | F6: Chi dự phòng | G6: Chi CTMTQG | J6: Tổng chi | K6: Chi ĐT phát triển (không kể CTMTQG) | L6: Chi TX (không kể CTMTQG) | M6: Chi dự phòng | N6: Chi CTMTQG | Q6: Chi chuyển nguồn | R6: Hủy dự toán về NS huyện | S6: Nộp trả NS cấp trên | T6: Tổng chi | U6: Chi ĐT | V6: Chi TX | W6: Chi CTMT-QG
G7: Tổng số | H7: Chi ĐT phát triển | I7: Chi TX | N7: Tổng số | O7: Chi ĐT phát triển | P7: Chi TX
A8: A | B8: B | C8: 1 | D8: 2 | E8: 3 | F8: 4 | G8: 5 | H8: 6 | I8: 7 | J8: 8 | K8: 9 | L8: 10 | M8: 11 | N8: 12 | O8: 13 | P8: 14 | Q8: 15 | R8: 16 | S8: 17 | T8: 18 | U8: 19 | V8: 20 | W8: 21
A9: I | B9: Các cơ quan tổ chức | C9: 126945 | D9: 5710 | E9: 99447 | G9: 21788 | H9: 15543 | I9: 6244 | J9: =+K9+L9+N9+S9+Q9 -> 138427 | K9: 5686 | L9: 97225 | N9: 21141 | O9: 15440 | P9: 5701 | Q9: =+Q79 -> 14300 | S9: 75 | T9: 97.72% | U9: 99.58% | V9: 97.77% | W9: 97.03%
A10: 1 | B10: Xã Quang Sơn | C10: 126945 | D10: 5710 | E10: 99447 | G10: 21788 | H10: 15543 | I10: 6244 | J10: 124052 | K10: 5686 | L10: 97225 | N10: 21141 | O10: 15440 | P10: 5701 | T10: 97.72% | U10: 99.58% | V10: 97.77% | W10: 97.03%
B11: UBND Xã Tân Long(1004603) | C11: 0 | D11: 0 | E11: 0 | G11: 0 | H11: 0 | I11: 0 | J11: 0 | K11: 0 | L11: 0 | N11: 0 | O11: 0 | P11: 0
B12: Trường tiểu học Tân Long huyện Đồng Hỷ(1006509) | C12: 7730 | D12: 0 | E12: 7730 | G12: 0 | H12: 0 | I12: 0 | J12: 7729 | K12: 0 | L12: 7729 | N12: 0 | O12: 0 | P12: 0 | T12: 99.99% | V12: 99.99%
B13: Trường tiểu học Quang Sơn(1006609) | C13: 7738 | D13: 0 | E13: 7738 | G13: 0 | H13: 0 | I13: 0 | J13: 7736 | K13: 0 | L13: 7736 | N13: 0 | O13: 0 | P13: 0 | T13: 99.97% | V13: 99.97%
B14: Trường TH cơ sở Quang Sơn(1038541) | C14: 5270 | D14: 0 | E14: 5270 | G14: 0 | H14: 0 | I14: 0 | J14: 5268 | K14: 0 | L14: 5268 | N14: 0 | O14: 0 | P14: 0 | T14: 99.96% | V14: 99.96%
B15: Trường tiểu học Sa Lung(1062126) | C15: 9135 | D15: 0 | E15: 9135 | G15: 0 | H15: 0 | I15: 0 | J15: 9133 | K15: 0 | L15: 9133 | N15: 0 | O15: 0 | P15: 0 | T15: 99.98% | V15: 99.98%
B16: Trường Phổ thông DTBT THCS Tân Long, huyện Đồng Hỷ(1072554) | C16: 10325 | D16: 0 | E16: 10325 | G16: 0 | H16: 0 | I16: 0 | J16: 10323 | K16: 0 | L16: 10323 | N16: 0 | O16: 0 | P16: 0 | T16: 99.98% | V16: 99.98%
B17: Trường mầm non Tân Long huyện Đồng Hỷ(1103187) | C17: 11576 | D17: 0 | E17: 11576 | G17: 0 | H17: 0 | I17: 0 | J17: 11569 | K17: 0 | L17: 11569 | N17: 0 | O17: 0 | P17: 0 | T17: 99.94% | V17: 99.94%
B18: Trường mầm non Quang Sơn huyện Đồng Hỷ(1112974) | C18: 5835 | D18: 0 | E18: 5835 | G18: 0 | H18: 0 | I18: 0 | J18: 5828 | K18: 0 | L18: 5828 | N18: 0 | O18: 0 | P18: 0 | T18: 99.88% | V18: 99.88%
B19: Phòng Kinh tế xã Quang Sơn(1155323) | C19: 6976 | D19: 0 | E19: 6659 | G19: 317 | H19: 0 | I19: 317 | J19: 6332 | K19: 0 | L19: 6136 | N19: 196 | O19: 0 | P19: 196 | T19: 90.77% | V19: 92.15% | W19: 61.83%
B20: Uỷ ban Mặt trận Tổ quốc Việt Nam xã Quang Sơn(1155512) | C20: 2072 | D20: 0 | E20: 2072 | G20: 0 | H20: 0 | I20: 0 | J20: 2070 | K20: 0 | L20: 2070 | N20: 0 | O20: 0 | P20: 0 | T20: 99.9% | V20: 99.9%
B21: Trung tâm phục vụ hành chính công xã Quang Sơn(1157740) | C21: 1422 | D21: 0 | E21: 1422 | G21: 0 | H21: 0 | I21: 0 | J21: 1420 | K21: 0 | L21: 1420 | N21: 0 | O21: 0 | P21: 0 | T21: 99.86% | V21: 99.86%
B22: Văn phòng Đảng uỷ xã Quang Sơn(1157741) | C22: 4172 | D22: 0 | E22: 4172 | G22: 0 | H22: 0 | I22: 0 | J22: 4152 | K22: 0 | L22: 4152 | N22: 0 | O22: 0 | P22: 0 | T22: 99.52% | V22: 99.52%
B23: Phòng Văn hoá- xã hội xã Quang Sơn(1157742) | C23: 7912 | D23: 0 | E23: 5660 | G23: 2252 | H23: 0 | I23: 2252 | J23: 6554 | K23: 0 | L23: 4399 | N23: 2155 | O23: 0 | P23: 2155 | T23: 82.84% | V23: 77.72% | W23: 95.69%
B24: Văn phòng HĐND và UBND xã Quang Sơn(1157743) | C24: 19886 | D24: 0 | E24: 19886 | G24: 0 | H24: 0 | I24: 0 | J24: 19751 | K24: 0 | L24: 19751 | N24: 0 | O24: 0 | P24: 0 | T24: 99.32% | V24: 99.32%
B25: Trung tâm Dịch vụ tổng hợp xã Quang Sơn(1164995) | C25: 5641 | D25: 0 | E25: 1966 | G25: 3675 | H25: 0 | I25: 3675 | J25: 5062 | K25: 0 | L25: 1712 | N25: 3350 | O25: 0 | P25: 3350 | T25: 89.74% | V25: 87.08% | W25: 91.16%
B26: Xây dựng cổng, sân, tường rào và các công trình phụ trợ khác nhà văn hóa xóm Đồng Luông xã Tân Long(8027524) | C26: 9 | D26: 0 | E26: 0 | G26: 9 | H26: 9 | I26: 0 | J26: 9 | K26: 0 | L26: 0 | N26: 9 | O26: 9 | P26: 0 | T26: 100% | W26: 100%
B27: Xây dựng cổng, sân, tường rào và các công trình phụ trợ khác nhà văn hóa xóm Làng Giếng xã Tân Long(8027525) | C27: 13 | D27: 0 | E27: 0 | G27: 13 | H27: 13 | I27: 0 | J27: 13 | K27: 0 | L27: 0 | N27: 13 | O27: 13 | P27: 0 | T27: 100% | W27: 100%
B28: Xây dựng nhà văn hóa xóm Làng Giếng xã Tân Long(8027526) | C28: 46 | D28: 0 | E28: 0 | G28: 46 | H28: 46 | I28: 0 | J28: 46 | K28: 0 | L28: 0 | N28: 46 | O28: 46 | P28: 0 | T28: 100% | W28: 100%
B29: Xây dựng tường rào, kè chắn đất UBND xã Tân Long(8027527) | C29: 4 | D29: 0 | E29: 0 | G29: 4 | H29: 4 | I29: 0 | J29: 4 | K29: 0 | L29: 0 | N29: 4 | O29: 4 | P29: 0 | T29: 100% | W29: 100%
B30: Xây dựng tường rào, sân, rãnh thoát nước và các công trình phụ trợ khác nhà văn hóa xóm Lân Quan xã Tân Long(8029097) | C30: 24 | D30: 0 | E30: 0 | G30: 24 | H30: 24 | I30: 0 | J30: 24 | K30: 0 | L30: 0 | N30: 24 | O30: 24 | P30: 0 | T30: 100% | W30: 100%
B31: Xây dựng cổng, sân, tường rào và các công trình phụ trợ khác nhà văn hóa xóm Hồng Phong xã Tân Long(8029098) | C31: 19 | D31: 0 | E31: 0 | G31: 19 | H31: 19 | I31: 0 | J31: 19 | K31: 0 | L31: 0 | N31: 19 | O31: 19 | P31: 0 | T31: 100% | W31: 100%
B32: Xây dựng cổng, sân, tường rào và các công trình phụ trợ khác nhà văn hóa xóm Mỏ Ba xã Tân Long(8029099) | C32: 24 | D32: 0 | E32: 0 | G32: 24 | H32: 24 | I32: 0 | J32: 24 | K32: 0 | L32: 0 | N32: 24 | O32: 24 | P32: 0 | T32: 100% | W32: 100%
B33: Xây dựng cổng, sân, tường rào và các công trình phụ trợ khác nhà văn hóa xóm Đồng Mây xã Tân Long(8029100) | C33: 32 | D33: 0 | E33: 0 | G33: 32 | H33: 32 | I33: 0 | J33: 32 | K33: 0 | L33: 0 | N33: 32 | O33: 32 | P33: 0 | T33: 100% | W33: 100%
B34: Nhà lớp học 2 tầng 6 phòng và các công trình phụ trợ trường tiểu học Sa Lung - Điểm trường Lân Quan(8029489) | C34: 1104 | D34: 0 | E34: 0 | G34: 1104 | H34: 1104 | I34: 0 | J34: 1104 | K34: 0 | L34: 0 | N34: 1104 | O34: 1104 | P34: 0 | T34: 100% | W34: 100%
B35: Nâng cấp sân trung tâm văn hóa thể thao xã Tân Long giai đoạn 2; Hạng mục: Mặt sân, đèn chiếu sáng, rãnh tiêu, thoát nước(8029925) | C35: 66 | D35: 0 | E35: 0 | G35: 66 | H35: 66 | I35: 0 | J35: 66 | K35: 0 | L35: 0 | N35: 66 | O35: 66 | P35: 0 | T35: 100% | W35: 100%
B36: Sửa chữa kênh mương xóm Đồng Luông xã Tân Long(8029926) | C36: 35 | D36: 0 | E36: 0 | G36: 35 | H36: 35 | I36: 0 | J36: 35 | K36: 0 | L36: 0 | N36: 35 | O36: 35 | P36: 0 | T36: 100% | W36: 100%
B37: Xây dựng tường rào trường Tiểu học Sa Lung khu trung tâm xã Tân Long(8030115) | C37: 10 | D37: 0 | E37: 0 | G37: 10 | H37: 10 | I37: 0 | J37: 10 | K37: 0 | L37: 0 | N37: 10 | O37: 10 | P37: 0 | T37: 100% | W37: 100%
... B46: Cải tạo mở rộng mặt đường bê tông tuyến đường liên xóm Đồng Tâm-Xuân Quang, xã Quang Sơn(8102456) | C46: 112 | D46: 0 | E46: 0 | G46: 112 | H46: 112 | I46: 0 | J46: 112 | K46: 0 | L46: 0 | N46: 112 | O46: 112 | P46: 0 | T46: 100% | W46: 100%
B47: Xây dựng nhà lớp học 2 tầng 8 phòng học Trường Mầm non Tân Long - Điểm Đồng Mây(8103446) | C47: 6495 | D47: 1993 | E47: 0 | G47: 4502 | H47: 4502 | I47: 0 | J47: 6472 | K47: 1970 | L47: 0 | N47: 4502 | O47: 4502 | P47: 0 | T47: 99.65% | U47: 98.85% | W47: 100%
B48: Xây dựng nhà hiệu bộ, phòng chức năng, bếp ăn một chiều và các công trình phụ trợ trường Mầm non Tân Long – Điểm trường trung tâm(8104228) | C48: 3306 | D48: 3306 | E48: 0 | G48: 0 | H48: 0 | I48: 0 | J48: 3306 | K48: 3306 | L48: 0 | N48: 0 | O48: 0 | P48: 0 | T48: 100% | U48: 100%
...

Sheet 58
Y1: Biểu mẫu số 58 Kèm theo Nghị định 31/2017/NĐ-CP ngày 23/3/2017 của Chính Phủ
A2: QUYẾT TOÁN CHI NGÂN SÁCH ĐỊA PHƯƠNG TỪNG ĐƠN VỊ NĂM 2025
A3: =+'48'!A3:F3 -> (Kèm theo Nghị quyết số 09 /NQ-HĐND ngày 30 tháng 3 năm 2026 của HĐND xã Quang Sơn)
AB4: Đơn vị: Triệu đồng
A5: STT | B5: Tên đơn vị | C5: Trong đó Dự toán | M5: Trong đó Quyết toán | W5: Chi nộp trả | X5: Chi chuyển nguồn sang năm sau | Y5: So sánh
C6: Tổng số Dự toán | D6: Chi đầu tư phát triển | G6: Chi thường xuyên | J6: Chi CTMTQG | M6: Tổng số Quyết toán | N6: Chi đầu tư phát triển | Q6: Chi thường xuyên | T6: Chi CTMTQG | Y6: Tổng số | Z6: Chi đầu tư phát triển | AA6: Chi thường xuyên | AB6: Chi CTMTQG
D7: Tổng số | E7: Trong đó | G7: Tổng số | H7: Trong đó | J7: Tổng số | K7: Trong đó | N7: Tổng số | O7: Trong đó | Q7: Tổng số | R7: Trong đó | T7: Tổng số | U7: Trong đó
E8: Chi giáo dục đào tạo dạy nghề | F8: Chi khoa học và công nghệ | H8: Chi giáo dục đào tạo dạy nghề | I8: Chi khoa học và công nghệ | K8: Chi đầu tư phát triển | L8: Chi thường xuyên | O8: Chi giáo dục đào tạo dạy nghề | P8: Chi khoa học và công nghệ | R8: Chi giáo dục đào tạo dạy nghề | S8: Chi khoa học và công nghệ | U8: Chi đầu tư phát triển | V8: Chi thường xuyên
A9: A | B9: B | C9: 1 | D9: 2 | E9: 3 | F9: 4 | G9: 5 | H9: 6 | I9: 7 | J9: 8 | K9: 9 | L9: 10 | M9: 11 | N9: 12 | O9: 13 | P9: 14 | Q9: 15 | R9: 16 | S9: 17 | T9: 18 | U9: 19 | V9: 20 | W9: 21 | X9: 22 | Y9: 23=11/1 | Z9: 24=12/2 | AA9: 25=15/5 | AB9: 26=18/8
B10: Tổng | C10: 126945 | D10: 5710 | E10: 5300 | F10: 0 | G10: 99447 | H10: 57758 | I10: 0 | J10: 21788 | K10: 15543 | L10: 6244 | M10: =+N10+Q10+W10+X10+T10 -> 138427 | N10: 5686 | O10: 5276 | P10: 0 | Q10: 97225 | R10: 57689 | S10: 0 | T10: 21141 | U10: 15440 | V10: 5701 | W10: 75 | X10: 14300 | Y10: =+M10/C10 -> 1.0904486 | Z10: 99.58% | AA10: 97.77% | AB10: 97.03%
A11: 1 | B11: 1006509 - Trường tiểu học Tân Long huyện Đồng Hỷ | C11: 7730 | D11: 0 | E11: 0 | F11: 0 | G11: 7730 | H11: 7730 | I11: 0 | J11: 0 | K11: 0 | L11: 0 | M11: 7729 | N11: 0 | O11: 0 | P11: 0 | Q11: 7729 | R11: 7729 | S11: 0 | T11: 0 | U11: 0 | V11: 0 | W11: 0 | X11: 0 | Y11: 99.99% | AA11: 99.99%
A12: 2 | B12: 1006609 - Trường tiểu học Quang Sơn | C12: 7738 | D12: 0 | E12: 0 | F12: 0 | G12: 7738 | H12: 7738 | I12: 0 | J12: 0 | K12: 0 | L12: 0 | M12: 7736 | N12: 0 | O12: 0 | P12: 0 | Q12: 7736 | R12: 7736 | S12: 0 | T12: 0 | U12: 0 | V12: 0 | W12: 0 | X12: 0 | Y12: 99.97% | AA12: 99.97%
A13: 3 | B13: 1038541 - Trường TH cơ sở Quang Sơn | C13: 5270 | D13: 0 | E13: 0 | F13: 0 | G13: 5270 | H13: 5270 | I13: 0 | J13: 0 | K13: 0 | L13: 0 | M13: 5268 | N13: 0 | O13: 0 | P13: 0 | Q13: 5268 | R13: 5268 | S13: 0 | T13: 0 | U13: 0 | V13: 0 | W13: 0 | X13: 0 | Y13: 99.96% | AA13: 99.96%
A14: 4 | B14: 1062126 - Trường tiểu học Sa Lung | C14: 9135 | D14: 0 | E14: 0 | F14: 0 | G14: 9135 | H14: 9135 | I14: 0 | J14: 0 | K14: 0 | L14: 0 | M14: 9133 | N14: 0 | O14: 0 | P14: 0 | Q14: 9133 | R14: 9133 | S14: 0 | T14: 0 | U14: 0 | V14: 0 | W14: 0 | X14: 0 | Y14: 99.98% | AA14: 99.98%
A15: 5 | B15: 1072554 - Trường Phổ thông DTBT THCS Tân Long, huyện Đồng Hỷ | C15: 10325 | D15: 0 | E15: 0 | F15: 0 | G15: 10325 | H15: 10325 | I15: 0 | J15: 0 | K15: 0 | L15: 0 | M15: 10323 | N15: 0 | O15: 0 | P15: 0 | Q15: 10323 | R15: 10323 | S15: 0 | T15: 0 | U15: 0 | V15: 0 | W15: 0 | X15: 0 | Y15: 99.98% | AA15: 99.98%
A16: 6 | B16: 1103187 - Trường mầm non Tân Long huyện Đồng Hỷ | C16: 11576 | D16: 0 | E16: 0 | F16: 0 | G16: 11576 | H16: 11576 | I16: 0 | J16: 0 | K16: 0 | L16: 0 | M16: 11569 | N16: 0 | O16: 0 | P16: 0 | Q16: 11569 | R16: 11569 | S16: 0 | T16: 0 | U16: 0 | V16: 0 | W16: 0 | X16: 0 | Y16: 99.94% | AA16: 99.94%
A17: 7 | B17: 1112974 - Trường mầm non Quang Sơn huyện Đồng Hỷ | C17: 5835 | D17: 0 | E17: 0 | F17: 0 | G17: 5835 | H17: 5835 | I17: 0 | J17: 0 | K17: 0 | L17: 0 | M17: 5828 | N17: 0 | O17: 0 | P17: 0 | Q17: 5828 | R17: 5828 | S17: 0 | T17: 0 | U17: 0 | V17: 0 | W17: 0 | X17: 0 | Y17: 99.88% | AA17: 99.88%
A18: 8 | B18: 1155323 - Phòng Kinh tế xã Quang Sơn | C18: 6976 | D18: 0 | E18: 0 | F18: 0 | G18: 6659 | H18: 0 | I18: 0 | J18: 317 | K18: 0 | L18: 317 | M18: 6332 | N18: 0 | O18: 0 | P18: 0 | Q18: 6136 | R18: 0 | S18: 0 | T18: 196 | U18: 0 | V18: 196 | W18: 0 | X18: 0 | Y18: 90.77% | AA18: 92.15% | AB18: 61.83%
A19: 9 | B19: 1155512 - Uỷ ban Mặt trận Tổ quốc Việt Nam xã Quang Sơn | C19: 2072 | D19: 0 | E19: 0 | F19: 0 | G19: 2072 | H19: 0 | I19: 0 | J19: 0 | K19: 0 | L19: 0 | M19: 2070 | N19: 0 | O19: 0 | P19: 0 | Q19: 2070 | R19: 0 | S19: 0 | T19: 0 | U19: 0 | V19: 0 | W19: 0 | X19: 0 | Y19: 99.9% | AA19: 99.9%
A20: 10 | B20: 1157740 - Trung tâm phục vụ hành chính công xã Quang Sơn | C20: 1422 | D20: 0 | E20: 0 | F20: 0 | G20: 1422 | H20: 0 | I20: 0 | J20: 0 | K20: 0 | L20: 0 | M20: 1420 | N20: 0 | O20: 0 | P20: 0 | Q20: 1420 | R20: 0 | S20: 0 | T20: 0 | U20: 0 | V20: 0 | W20: 0 | X20: 0 | Y20: 99.86% | AA20: 99.86%
A21: 11 | B21: 1157741 - Văn phòng Đảng uỷ xã Quang Sơn | C21: 4172 | D21: 0 | E21: 0 | F21: 0 | G21: 4172 | H21: 0 | I21: 0 | J21: 0 | K21: 0 | L21: 0 | M21: 4152 | N21: 0 | O21: 0 | P21: 0 | Q21: 4152 | R21: 0 | S21: 0 | T21: 0 | U21: 0 | V21: 0 | W21: 0 | X21: 0 | Y21: 99.52% | AA21: 99.52%
A22: 12 | B22: 1157742 - Phòng Văn hoá- xã hội xã Quang Sơn | C22: 7912 | D22: 0 | E22: 0 | F22: 0 | G22: 5660 | H22: 147 | I22: 0 | J22: 2252 | K22: 0 | L22: 2252 | M22: 6554 | N22: 0 | O22: 0 | P22: 0 | Q22: 4399 | R22: 102 | S22: 0 | T22: 2155 | U22: 0 | V22: 2155 | W22: 0 | X22: 0 | Y22: 82.84% | AA22: 77.72% | AB22: 95.69%
A23: 13 | B23: 1157743 - Văn phòng HĐND và UBND xã Quang Sơn | C23: 19886 | D23: 0 | E23: 0 | F23: 0 | G23: 19886 | H23: 0 | I23: 0 | J23: 0 | K23: 0 | L23: 0 | M23: 19751 | N23: 0 | O23: 0 | P23: 0 | Q23: 19751 | R23: 0 | S23: 0 | T23: 0 | U23: 0 | V23: 0 | W23: 0 | X23: 0 | Y23: 99.32% | AA23: 99.32%
A24: 14 | B24: 1164995 - Trung tâm Dịch vụ tổng hợp xã Quang Sơn | C24: 5641 | D24: 0 | E24: 0 | F24: 0 | G24: 1966 | H24: 0 | I24: 0 | J24: 3675 | K24: 0 | L24: 3675 | M24: 5062 | N24: 0 | O24: 0 | P24: 0 | Q24: 1712 | R24: 0 | S24: 0 | T24: 3350 | U24: 0 | V24: 3350 | W24: 0 | X24: 0 | Y24: 89.74% | AA24: 87.08% | AB24: 91.16%
A25: 15 | B25: 2805674 - Mã tổ chức ngân sách Xã Quang Sơn | C25: 0 | D25: 0 | E25: 0 | F25: 0 | G25: 0 | H25: 0 | I25: 0 | J25: 0 | K25: 0 | L25: 0 | M25: 75 | N25: 0 | O25: 0 | P25: 0 | Q25: 0 | R25: 0 | S25: 0 | T25: 0 | U25: 0 | V25: 0 | W25: 75 | X25: 0
A26: 16 | B26: 8027524 - Xây dựng cổng, sân, tường rào và các công trình phụ trợ khác nhà văn hóa xóm Đồng Luông xã Tân Long | C26: 9 | D26: 0 | E26: 0 | F26: 0 | G26: 0 | H26: 0 | I26: 0 | J26: 9 | K26: 9 | L26: 0 | M26: 9 | N26: 0 | O26: 0 | P26: 0 | Q26: 0 | R26: 0 | S26: 0 | T26: 9 | U26: 9 | V26: 0 | W26: 0 | X26: 0 | Y26: 100% | AB26: 100%
A27: 17 | B27: 8027525 - Xây dựng cổng, sân, tường rào và các công trình phụ trợ khác nhà văn hóa xóm Làng Giếng xã Tân Long | C27: 13 | D27: 0 | E27: 0 | F27: 0 | G27: 0 | H27: 0 | I27: 0 | J27: 13 | K27: 13 | L27: 0 | M27: 13 | N27: 0 | O27: 0 | P27: 0 | Q27: 0 | R27: 0 | S27: 0 | T27: 13 | U27: 13 | V27: 0 | W27: 0 | X27: 0 | Y27: 100% | AB27: 100%
A28: 18 | B28: 8027526 - Xây dựng nhà văn hóa xóm Làng Giếng xã Tân Long | C28: 46 | D28: 0 | E28: 0 | F28: 0 | G28: 0 | H28: 0 | I28: 0 | J28: 46 | K28: 46 | L28: 0 | M28: 46 | N28: 0 | O28: 0 | P28: 0 | Q28: 0 | R28: 0 | S28: 0 | T28: 46 | U28: 46 | V28: 0 | W28: 0 | X28: 0 | Y28: 100% | AB28: 100%
A29: 19 | B29: 8027527 - Xây dựng tường rào, kè chắn đất UBND xã Tân Long | C29: 4 | D29: 0 | E29: 0 | F29: 0 | G29: 0 | H29: 0 | I29: 0 | J29: 4 | K29: 4 | L29: 0 | M29: 4 | N29: 0 | O29: 0 | P29: 0 | Q29: 0 | R29: 0 | S29: 0 | T29: 4 | U29: 4 | V29: 0 | W29: 0 | X29: 0 | Y29: 100% | AB29: 100%
A30: 20 | B30: 8029097 - Xây dựng tường rào, sân, rãnh thoát nước và các công trình phụ trợ khác nhà văn hóa xóm Lân Quan xã Tân Long | C30: 24 | D30: 0 | E30: 0 | F30: 0 | G30: 0 | H30: 0 | I30: 0 | J30: 24 | K30: 24 | L30: 0 | M30: 24 | N30: 0 | O30: 0 | P30: 0 | Q30: 0 | R30: 0 | S30: 0 | T30: 24 | U30: 24 | V30: 0 | W30: 0 | X30: 0 | Y30: 100% | AB30: 100%
A31: 21 | B31: 8029098 - Xây dựng cổng, sân, tường rào và các công trình phụ trợ khác nhà văn hóa xóm Hồng Phong xã Tân Long | C31: 19 | D31: 0 | E31: 0 | F31: 0 | G31: 0 | H31: 0 | I31: 0 | J31: 19 | K31: 19 | L31: 0 | M31: 19 | N31: 0 | O31: 0 | P31: 0 | Q31: 0 | R31: 0 | S31: 0 | T31: 19 | U31: 19 | V31: 0 | W31: 0 | X31: 0 | Y31: 100% | AB31: 100%
A32: 22 | B32: 8029099 - Xây dựng cổng, sân, tường rào và các công trình phụ trợ khác nhà văn hóa xóm Mỏ Ba xã Tân Long | C32: 24 | D32: 0 | E32: 0 | F32: 0 | G32: 0 | H32: 0 | I32: 0 | J32: 24 | K32: 24 | L32: 0 | M32: 24 | N32: 0 | O32: 0 | P32: 0 | Q32: 0 | R32: 0 | S32: 0 | T32: 24 | U32: 24 | V32: 0 | W32: 0 | X32: 0 | Y32: 100% | AB32: 100%
A33: 23 | B33: 8029100 - Xây dựng cổng, sân, tường rào và các công trình phụ trợ khác nhà văn hóa xóm Đồng Mây xã Tân Long | C33: 32 | D33: 0 | E33: 0 | F33: 0 | G33: 0 | H33: 0 | I33: 0 | J33: 32 | K33: 32 | L33: 0 | M33: 32 | N33: 0 | O33: 0 | P33: 0 | Q33: 0 | R33: 0 | S33: 0 | T33: 32 | U33: 32 | V33: 0 | W33: 0 | X33: 0 | Y33: 100% | AB33: 100%
A34: 24 | B34: 8029489 - Nhà lớp học 2 tầng 6 phòng và các công trình phụ trợ trường tiểu học Sa Lung - Điểm trường Lân Quan | C34: 1104 | D34: 0 | E34: 0 | F34: 0 | G34: 0 | H34: 0 | I34: 0 | J34: 1104 | K34: 1104 | L34: 0 | M34: 1104 | N34: 0 | O34: 0 | P34: 0 | Q34: 0 | R34: 0 | S34: 0 | T34: 1104 | U34: 1104 | V34: 0 | W34: 0 | X34: 0 | Y34: 100% | AB34: 100%
A35: 25 | B35: 8029925 - Nâng cấp sân trung tâm văn hóa thể thao xã Tân Long giai đoạn 2; Hạng mục: Mặt sân, đèn chiếu sáng, rãnh tiêu, thoát nước | C35: 66 | D35: 0 | E35: 0 | F35: 0 | G35: 0 | H35: 0 | I35: 0 | J35: 66 | K35: 66 | L35: 0 | M35: 66 | N35: 0 | O35: 0 | P35: 0 | Q35: 0 | R35: 0 | S35: 0 | T35: 66 | U35: 66 | V35: 0 | W35: 0 | X35: 0 | Y35: 100% | AB35: 100%
A36: 26 | B36: 8029926 - Sửa chữa kênh mương xóm Đồng Luông xã Tân Long | C36: 35 | D36: 0 | E36: 0 | F36: 0 | G36: 0 | H36: 0 | I36: 0 | J36: 35 | K36: 35 | L36: 0 | M36: 35 | N36: 0 | O36: 0 | P36: 0 | Q36: 0 | R36: 0 | S36: 0 | T36: 35 | U36: 35 | V36: 0 | W36: 0 | X36: 0 | Y36: 100% | AB36: 100%
A37: 27 | B37: 8030115 - Xây dựng tường rào trường Tiểu học Sa Lung khu trung tâm xã Tân Long | C37: 10 | D37: 0 | E37: 0 | F37: 0 | G37: 0 | H37: 0 | I37: 0 | J37: 10 | K37: 10 | L37: 0 | M37: 10 | N37: 0 | O37: 0 | P37: 0 | Q37: 0 | R37: 0 | S37: 0 | T37: 10 | U37: 10 | V37: 0 | W37: 0 | X37: 0 | Y37: 100% | AB37: 100%
... A46: 36 | B46: 8102456 - Cải tạo mở rộng mặt đường bê tông tuyến đường liên xóm Đồng Tâm-Xuân Quang, xã Quang Sơn | C46: 112 | D46: 0 | E46: 0 | F46: 0 | G46: 0 | H46: 0 | I46: 0 | J46: 112 | K46: 112 | L46: 0 | M46: 112 | N46: 0 | O46: 0 | P46: 0 | Q46: 0 | R46: 0 | S46: 0 | T46: 112 | U46: 112 | V46: 0 | W46: 0 | X46: 0 | Y46: 100% | AB46: 100%
A47: 37 | B47: 8103446 - Xây dựng nhà lớp học 2 tầng 8 phòng học Trường Mầm non Tân Long - Điểm Đồng Mây | C47: 6495 | D47: 1993 | E47: 1993 | F47: 0 | G47: 0 | H47: 0 | I47: 0 | J47: 4502 | K47: 4502 | L47: 0 | M47: 6472 | N47: 1970 | O47: 1970 | P47: 0 | Q47: 0 | R47: 0 | S47: 0 | T47: 4502 | U47: 4502 | V47: 0 | W47: 0 | X47: 0 | Y47: 99.65% | Z47: 98.85% | AB47: 100%
A48: 38 | B48: 8104228 - Xây dựng nhà hiệu bộ, phòng chức năng, bếp ăn một chiều và các công trình phụ trợ trường Mầm non Tân Long – Điểm trường trung tâm | C48: 3306 | D48: 3306 | E48: 3306 | F48: 0 | G48: 0 | H48: 0 | I48: 0 | J48: 0 | K48: 0 | L48: 0 | M48: 3306 | N48: 3306 | O48: 3306 | P48: 0 | Q48: 0 | R48: 0 | S48: 0 | T48: 0 | U48: 0 | V48: 0 | W48: 0 | X48: 0 | Y48: 100% | Z48: 100%
...

Sheet 59
W1: Biểu mẫu số 59 Kèm theo Nghị định 31/2017/NĐ-CP ngày 23/3/2017 của Chính Phủ
A2: QUYẾT TOÁN CHI BỔ SUNG TỪ NGÂN SÁCH CẤP TỈNH CHO NGÂN SÁCH XÃ NĂM 2025
A3: =+'48'!A3:F3 -> (Kèm theo Nghị quyết số 09 /NQ-HĐND ngày 30 tháng 3 năm 2026 của HĐND xã Quang Sơn)
Z4: Đơn vị: Triệu đồng
A5: STT | B5: Tên đơn vị (1) | C5: Dự toán | K5: Quyết toán | S5: So sách (%)
C6: Tổng số | D6: Bổ sung cân đối ngân sách | E6: Bổ sung có mục tiêu | K6: Tổng số | L6: Bổ sung cân đối ngân sách | M6: Bổ sung có mục tiêu | S6: Tổng số | T6: Bổ sung cân đối ngân sách | U6: Bổ sung có mục tiêu
E7: Tổng số | F7: Gồm | H7: Vốn đầu tư để thực hiện các CTMT, nhiệm vụ | I7: Vốn sự nghiệp thực hiện các chế độ, chính sách | J7: Vốn thực hiện các CTMT quốc gia | M7: Tổng số | N7: Gồm | P7: Vốn đầu tư để thực hiện các CTMT, nhiệm vụ | Q7: Vốn sự nghiệp thực hiện các chế độ, chính sách | R7: Vốn thực hiện các CTMT quốc gia | U7: Tổng số | V7: Gồm | X7: Vốn đầu tư để thực hiện các CTMT, nhiệm vụ | Y7: Vốn sự nghiệp thực hiện các chế độ, chính sách | Z7: Vốn thực hiện các CTMT quốc gia
F8: Vốn ngoài nước | G8: Vốn trong nước | N8: Vốn ngoài nước | O8: Vốn trong nước | V8: Vốn ngoài nước | W8: Vốn trong nước
A9: A | B9: B | C9: 1 | D9: 2 | E9: 3=4+5 | F9: 4 | G9: 5 | H9: 6 | I9: 7 | J9: 8 | K9: 9 | L9: 10 | M9: 11=12+13 | N9: 12 | O9: 13 | P9: 14 | Q9: 15 | R9: 16 | S9: 17=9/1 | T9: 18=10/2 | U9: 19=11/3 | V9: 20=12/4 | W9: 21=13/5 | X9: 22=14/6 | Y9: 23=15/7 | Z9: 24=16/8
B10: TỔNG SỐ | C10: =+D10+E10 -> 110863 | D10: =+SUM(D11:D11) -> 14866 | E10: =+F10+G10 -> 95997 | F10: =+SUM(F11:F11) -> 0 | G10: =+SUM(G11:G11) -> 95997 | H10: =+SUM(H11:H11) -> 476 | I10: =+SUM(I11:I11) -> 78218 | J10: =+SUM(J11:J11) -> 17303 | K10: =+L10+M10 -> 142247.01 | L10: =+SUM(L11:L11) -> 14866 | M10: =+N10+O10 -> 127381.01 | N10: =+SUM(N11:N11) -> 0 | O10: =+SUM(O11:O11) -> 127381.01 | P10: =+SUM(P11:P11) -> 7892.701 | Q10: =+SUM(Q11:Q11) -> 100386.31 | R10: =+SUM(R11:R11) -> 19102 | S10: =+K10/C10 -> 1.2830882 | T10: =+L10/D10 -> 1 | U10: =+M10/E10 -> 1.326927 | W10: =+O10/G10 -> 1.326927 | X10: =+P10/H10 -> 16.581305 | Y10: =+Q10/I10 -> 1.283417 | Z10: =+R10/J10 -> 1.1039704
B11: Xã Quang Sơn | C11: =+D11+E11 -> 110863 | D11: 14866 | E11: =+F11+G11 -> 95997 | G11: =+H11+I11+J11 -> 95997 | H11: 476 | I11: =95997-H11-J11 -> 78218 | J11: =17303 -> 17303 | K11: =+L11+M11 -> 142247.01 | L11: 14866 | M11: =+N11+O11 -> 127381.01 | O11: =+P11+Q11+R11 -> 127381.01 | P11: 7892.701 | Q11: =127381.009682-R11-P11 -> 100386.31 | R11: =17303+1799 -> 19102 | S11: =+K11/C11 -> 1.2830882 | T11: =+L11/D11 -> 1 | U11: =+M11/E11 -> 1.326927 | W11: =+O11/G11 -> 1.326927 | X11: =+P11/H11 -> 16.581305 | Y11: =+Q11/I11 -> 1.283417 | Z11: =+R11/J11 -> 1.1039704
P12: 0

Sheet 61
N1: Biểu mẫu số 61 Kèm theo Nghị định 31/2017/NĐ-CP ngày 23/3/2017 của Chính Phủ
A2: QUYẾT TOÁN CHI CHƯƠNG TRÌNH MỤC TIÊU QUỐC GIA NGÂN SÁCH XÃ NĂM 2025
A3: =+'48'!A3:F3 -> (Kèm theo Nghị quyết số 09 /NQ-HĐND ngày 30 tháng 3 năm 2026 của HĐND xã Quang Sơn)
Q4: Đơn vị: Triệu đồng
A5: STT | B5: Nội dung | C5: Dự toán | G5: Quyết toán
C6: Tổng số | D6: Trong đó | F6: … | G6: Tổng số | H6: Trong đó | J6: Chương trình mục tiêu quốc gia 2025 | Q6: …
D7: Đầu tư phát triển | E7: Kinh phí sự nghiệp | H7: Đầu tư phát triển | I7: Kinh phí sự nghiệp | J7: Tổng số | K7: Đầu tư phát triển | N7: Kinh phí sự nghiệp
K8: Tổng số | L8: Vốn trong nước | M8: Vốn ngoài nước | N8: Tổng số | O8: Vốn trong nước | P8: Vốn ngoài nước
A9: A | B9: B | C9: 1 | D9: 2 | E9: 3 | F9: 4 | G9: 5=6+7 | H9: 6 | I9: 7 | J9: 8=9+12 | K9: 9=10+11 | L9: 10 | M9: 11 | N9: 12=13+14 | O9: 13 | P9: 14 | Q9: 15
B10: TỔNG SỐ | C10: =+D10+E10 -> 21794.325 | D10: =+SUM(D11:D13) -> 15549.926 | E10: =+SUM(E11:E13) -> 6244.3988 | F10: =+SUM(F11:F12) -> 0 | G10: =+SUM(G11:G13) -> 21140.824 | H10: =+SUM(H11:H13) -> 15439.519 | I10: =+SUM(I11:I13) -> 5701.3055 | J10: =+SUM(J11:J13) -> 21140.824 | K10: =+SUM(K11:K13) -> 15439.519 | L10: =+SUM(L11:L13) -> 15439.519 | M10: =+SUM(M11:M13) -> 0 | N10: =+SUM(N11:N13) -> 5701.3055 | ... P10: =+SUM(P11:P13) -> 0
B11: 1155323 - Phòng Kinh tế xã Quang Sơn | C11: =+SUM(D11:E11) -> 316.86 | E11: 316.86 | G11: =+H11+I11 -> 195.9848 | H11: =+K11 -> 0 | I11: =+N11 -> 195.9848 | J11: =+K11+N11 -> 195.9848 | K11: =+L11+M11 -> 0 | N11: =+O11+P11 -> 195.9848 | O11: 195.9848
B12: 1157742 - Phòng Văn hoá- xã hội xã Quang Sơn | C12: =+SUM(D12:E12) -> 2252.4404 | E12: 2252.4404 | G12: =+H12+I12 -> 2155.4653 | H12: =+K12 -> 0 | I12: =+N12 -> 2155.4653 | J12: =+K12+N12 -> 2155.4653 | K12: =+L12+M12 -> 0 | N12: =+O12+P12 -> 2155.4653 | O12: 2155.4653
B13: 1164995 - Trung tâm Dịch vụ tổng hợp xã Quang Sơn | C13: =+SUM(D13:E13) -> 19225.024 | D13: 15549.926 | E13: 3675.0984 | G13: =+H13+I13 -> 18789.374 | H13: =+K13 -> 15439.519 | I13: =+N13 -> 3349.8555 | J13: =+K13+N13 -> 18789.374 | K13: =+L13+M13 -> 15439.519 | L13: 15439.519 | N13: =+O13+P13 -> 3349.8555 | O13: 3349.8555
J14: =+K14+N14 -> 0 | K14: =+L14+M14 -> 0 | N14: =+O14+P14 -> 0
