Workbook

Sheet 01-Cân đôi
D1: Biểu số 01
A2: CÂN ĐỐI NGÂN SÁCH ĐỊA PHƯƠNG NĂM 2025
A3: (Kèm theo Nghị quyết số /NQ-HĐND ngày tháng 9 năm 2025 của HĐND xã Quang Sơn)
B4: Đơn vị tính: Triệu đồng
A5: STT | B5: Nội dung | C5: Dự toán năm 2025 | D5: Ghi chú
A7: A | B7: Thu ngân sách địa phương | C7: =C8+C11+C14+C16+C15 -> 124134
A8: I | B8: Thu NSĐP được hưởng theo phân cấp | C8: =C9+C10 -> 0
B9: Thu NSĐP hưởng 100% | C9: 0
B10: Thu NSĐP hưởng từ các khoản thu phân chia | C10: 0
A11: II | B11: Thu bổ sung từ ngân sách cấp trên | C11: =C12+C13 -> 110863
B12: Bổ sung cân đối | C12: 14866 | E12: =+C9-C12 -> -14866
B13: Bổ sung có mục tiêu | C13: 95997
A14: III | B14: Thu chuyển nguồn CCTL từ năm trước sang | C14: 5281
A15: IV | B15: Thu kết dư ngân sách | C15: 4868
A16: V | B16: Thu viện trợ, ủng hộ, đóng góp | C16: 3122
A17: B | B17: TỔNG CHI NGÂN SÁCH ĐỊA PHƯƠNG | C17: =C18+C25+C30+C29+C28 -> 124134.06 | E17: =+C11-C17 -> -13271.06
A18: I | B18: Tổng chi cân đối NSĐP | C18: =SUM(C19:C24) -> 93325
A19: 1 | B19: Chi đầu tư phát triển từ nguồn tiền đất | C19: 2683
A20: 2 | B20: Chi thường xuyên | C20: 88821
A21: 3 | B21: Chi trả nợ lãi các khoản do chính quyền địa phương vay
A22: 4 | B22: Chi bổ sung quỹ dự trữ tài chính
A23: 5 | B23: Dự phòng ngân sách | C23: 1821
A24: 6 | B24: Chi tạo nguồn, điều chỉnh tiền lương
A25: II | B25: Chi các chương trình mục tiêu | C25: =SUM(C26:C27) -> 17538.06
A26: - | B26: Chi các chương trình mục tiêu quốc gia | C26: 17303.06
A27: - | B27: Chi các chương trình mục tiêu nhiệm vụ | C27: 235 | D27: Phân bổ sau
A28: III | B28: Chi từ chuyển nguồn | C28: 5281
A29: IV | B29: Chi từ nguồn kết dư | C29: 4868
A30: III | B30: ='[1]bieu 2,3'!B39 -> Chi từ nguồn viện trợ, huy động, đóng góp | C30: 3122
A31: C | B31: BỘI CHI NSĐP
A32: D | B32: CHI TRẢ NỢ GỐC CỦA NSĐP | C32: =#REF!+#REF! -> #REF!
A33: 1 | B33: Chi từ nguồn vay để trả nợ gốc | C33: =#REF!+#REF! -> #REF!
A34: 2 | B34: Chi từ nguồn bội thu, tăng thu, tiết kiệm chi, kết dư ngân sách cấp tỉnh | C34: =#REF!+#REF! -> #REF!
A35: E | B35: TỔNG MỨC VAY CỦA NSĐP | C35: =#REF!+#REF! -> #REF!
A36: 1 | B36: Vay để bù đắp bội chi | C36: =#REF!+#REF! -> #REF!
A37: 2 | B37: Vay để trả nợ gốc | C37: =#REF!+#REF! -> #REF!

Sheet 02-Thu theo lĩnh vực
D1: Biểu số 02
A2: DỰ TOÁN THU NGÂN SÁCH NHÀ NƯỚC THEO LINH VỰC NĂM 2025
A3: ='01-Cân đôi'!A3:C3 -> (Kèm theo Nghị quyết số /NQ-HĐND ngày tháng 9 năm 2025 của HĐND xã Quang Sơn)
C4: ĐVT: Triệu đồng
A5: STT | B5: Chỉ tiêu | C5: Tổng thu NSNN | D5: Thu NSĐP
A7: 1 | B7: 2 | C7: 3 | D7: 4
B8: THU NSNN TRÊN ĐỊA BÀN | C8: =C11+C50+C51 -> 17729.279 | D8: =D11+D50+D51 -> 0
B9: Thu NSNN trên địa bàn trừ tiền sử dụng đất, thu từ hoạt động xổ số kiến thiết | C9: =C8-C33-C47 -> 17519.279
B10: Thu NSNN trên địa bàn trừ tiền sử dụng đất, thu từ hoạt động xổ số kiến thiết, thuế tối thiểu toàn cầu | C10: =C9-2910000 -> -2892480.7
A11: I | B11: THU NỘI ĐỊA | C11: =C12+C17+C22+C27+C32+C33+C34+C35+C36+C37+C40+C43+C46+C47+C48+C49 -> 17729.279 | D11: =D12+D17+D22+D27+D32+D33+D34+D35+D36+D37+D40+D43+D46+D47+D48+D49 -> 0
A12: 1 | B12: Thu từ khu vực DNNN trung ương quản lý | C12: =SUM(C13:C16) -> 0 | D12: =SUM(D13:D16) -> 0
B13: Thuế giá trị gia tăng
B14: Thuế tiêu thụ đặc biệt
B15: Thuế thu nhập doanh nghiệp
B16: Thuế tài nguyên
A17: 2 | B17: Thu từ khu vực DNNN địa phương quản lý | C17: =SUM(C18:C21) -> 0 | D17: =SUM(D18:D21) -> 0
B18: Thuế giá trị gia tăng
B19: Thuế tiêu thụ đặc biệt
B20: Thuế thu nhập doanh nghiệp
B21: Thuế tài nguyên
A22: 3 | B22: Thu từ khu vực doanh nghiệp có vốn đầu tư nước ngoài | C22: =SUM(C23:C26) -> 0 | D22: =SUM(D23:D26) -> 0
B23: Thuế giá trị gia tăng
B24: Thuế tối thiểu toàn cầu
B25: Thuế tài nguyên
B26: Thuế thu nhập doanh nghiệp
A27: 4 | B27: Thu từ khu vực kinh tế ngoài quốc doanh | C27: 6019 | D27: =SUM(D28:D31) -> 0
B28: Thuế giá trị gia tăng | C28: 6019
B29: Thuế tiêu thụ đặc biệt
B30: Thuế thu nhập doanh nghiệp
B31: Thuế tài nguyên
A32: 5 | B32: Thuế thu nhập cá nhân | C32: 398
A33: 6 | B33: Tiền sử dụng đất | C33: 210
A34: 7 | B34: Thuế sử dụng đất phi nông nghiệp | C34: 30
A35: 8 | B35: Thu tiền cho thuê mặt đất, mặt nước | C35: 5192
A36: 9 | B36: Lệ phí trước bạ | C36: 1456
A37: 10 | B37: Phí, lệ phí | C37: =SUM(C38:C39) -> 1303 | D37: =SUM(D38:D39) -> 0
B38: Phí, lệ phí trung ương
B39: Phí, lệ phí địa phương | C39: 1303
A40: 11 | B40: Thuế bảo vệ môi trường
B41: Thu từ hàng hoá nhập khẩu | C41: =#REF!+#REF! -> #REF! | D41: =#REF!+#REF! -> #REF!
...

Sheet 03-Chi theo cơ cấu
A1: Biểu số 03
A2: DỰ TOÁN CHI NGÂN SÁCH ĐỊA PHƯƠNG THEO CƠ CẤU CHI NĂM 2025
A3: ='02-Thu theo lĩnh vực'!A3:D3 -> (Kèm theo Nghị quyết số /NQ-HĐND ngày tháng 9 năm 2025 của HĐND xã Quang Sơn)
C4: ĐVT: Triệu đồng
A5: STT | B5: Nội dung | C5: Dự toán năm 2025 | D5: Ghi chú
A6: 1 | B6: 2 | C6: 3 | D6: 4
B7: TỔNG CHI NGÂN SÁCH ĐỊA PHƯƠNG | C7: =+C8+C39+C40+C41+C42 -> 124134.06
A8: A | B8: CHI CÂN ĐỐI NSĐP | C8: =+C9+C21+C37+C36+C35+C38 -> 93325 | E8: 70908
A9: I | B9: Chi đầu tư phát triển | C9: =+SUM(C10:C14) -> 2683 | E9: =+E8-C8 -> -22417
A10: 1 | B10: Chi xây dựng cơ bản
A11: 2 | B11: Chi đầu tư từ nguồn thu tiền sử dụng đất | C11: 2683 | D11: Biểu số 06
A12: 3 | B12: Chi đầu tư từ nguồn thu xổ số kiến thiết
A13: 4 | B13: Chi GPMB từ nguồn thu tiền thuê đất
A14: 5 | B14: Chi đầu tư khác
B15: Chi trả nợ gốc | C15: 74676
B16: Kinh phí mua xi măng | C16: 96000
B17: Uỷ thác qua ngân hàng chính sách | C17: 60000
B18: Hỗ trợ huyện Đồng Hỷ theo kết luận của Ban Thường vụ Tỉnh uỷ | C18: 30000
B19: Hỗ trợ huyện Phú Bình xây dựng khu tái định cư phục vụ dự án Khu công nghệ thông tin tập trung Yên Bình | C19: 20000
B20: Trả tiền thuê hạ tầng cho các công ty thuộc tập đoàn Samsung | C20: 125000
A21: II | B21: Chi thường xuyên | C21: =+SUM(C23:C34) -> 88821
B22: Trong đó
A23: 1 | B23: Chi sự nghiệp giáo dục đào tạo và dạy nghề | C23: =+'04-chi cac don vi'!F10 -> 57971
A24: 2 | B24: Chi sự nghiệp y tế, dân số và gia đình | C24: =+'04-chi cac don vi'!G10 -> 508
A25: 3 | B25: Chi sự nghiệp khoa học và công nghệ | C25: =+'04-chi cac don vi'!H10 -> 30
A26: 4 | B26: Chi sự nghiệp văn hoá thông tin | C26: =+'04-chi cac don vi'!I10 -> 248
A27: 5 | B27: Chi sự nghiệp thể dục thể thao | C27: =+'04-chi cac don vi'!J10 -> 163
A28: 6 | B28: Chi sự nghiệp phát thanh truyền hình | C28: =+'04-chi cac don vi'!K10 -> 136
A29: 7 | B29: Chi đảm bảo xã hội | C29: =+'04-chi cac don vi'!L10 -> 2683
A30: 8 | B30: Sự nghiệp kinh tế, môi trường | C30: =+'04-chi cac don vi'!M10 -> 4739
A31: 9 | B31: Chi quản lý hành chính | C31: =+'04-chi cac don vi'!N10 -> 19012
A32: 10 | B32: Chi quốc phòng | C32: =+'04-chi cac don vi'!O10 -> 980
A33: 11 | B33: Chi an ninh địa phương | C33: =+'04-chi cac don vi'!P10 -> 789
A34: 12 | B34: Chi cải cách tiền lương | C34: =+'04-chi cac don vi'!Q10 -> 1562
A35: III | B35: Chi trả nợ lãi các khoản do chính quyền địa phương vay
A36: IV | B36: Chi bổ sung quỹ dự trữ tài chính
A37: V | B37: Dự phòng ngân sách | C37: 1821
A38: VI | B38: Chi tạo nguồn điều chỉnh tiền lương
A39: B | B39: CHI CÁC CHƯƠNG TRÌNH MỤC TIÊU | C39: 17538.06 | D39: Biểu số 05
A40: C | B40: Chi từ chuyển nguồn | C40: 5281 | D40: Biểu số 07
...

Sheet 04-chi cac don vi
P1: Biểu số 04
A2: DỰ TOÁN CHI CỦA NGÂN SÁCH CẤP XÃ CHO TỪNG CƠ QUAN, TỔ CHỨC THEO LĨNH VỰC NĂM 2025
A3: =+'01-Cân đôi'!A3:D3 -> (Kèm theo Nghị quyết số /NQ-HĐND ngày tháng 9 năm 2025 của HĐND xã Quang Sơn)
E4: =+SUM(F4:Q4) -> 88764 | F4: 57972 | G4: 508 | I4: 411 | K4: 136 | L4: 2683 | M4: =4522+217 -> 4739 | N4: =18049+48+607+80+200 -> 18984 | O4: 980 | P4: 790 | Q4: =1120+441 -> 1561
E5: =+E4-S10 -> -57 | G5: =+G4-G10 -> 0 | I5: =+I4-I10-J10 -> 0 | K5: =+K4-K10 -> 0 | L5: =+L4-L10 -> 0 | M5: =+M4-M10 -> 0 | N5: =+N4-N10 -> -28 | O5: =+O4-O10 -> 0 | P5: =+P4-P10 -> 1
O6: Đơn vị tính: Triệu đồng
A7: TT | B7: NỘI DUNG | C7: Tổng dự toán chi năm 2025 | D7: Dự toán chi đầu tư | E7: Dự toán chi thường xuyên năm 2025 | F7: Trong đó | U7: DT | V7: Còn dư
F8: Sự nghiệp giáo dục đào tạo | G8: Sự nghiệp y tế | H8: Sự nghiệp khoa học công nghệ | I8: Sự nghiệp văn hóa, thông tin | J8: Sự nghiệp thể dục, thể thao | K8: Sự nghiệp truyền thanh, truyền hình | L8: Đảm bảo xã hội | M8: Sự nghiệp kinh tế, môi trường | N8: Quản lý hành chính | O8: Chi quốc phòng | P8: Chi an ninh | Q8: Chi cải cách tiền lương | U8: 1562 | V8: =+U8-Q10 -> 0
A9: A | B9: B | C9: 1=2+3 | D9: 2 | E9: 1 | F9: 2 | G9: 3 | H9: 4 | I9: 5 | J9: 6 | K9: 7 | L9: 8 | M9: 9 | N9: 10 | O9: 11 | P9: 12 | Q9: 13
B10: TỔNG CỘNG | C10: =C11+C21+C32+C53+C78+C100+C104+C113+C120 -> #REF! | D10: =D11+D21+D32+D53+D78+D100+D104+D113+D120 -> #REF! | E10: =E11+E21+E32+E53+E78+E100+E104+E113+E120 -> 88821 | F10: =F11+F21+F32+F53+F78+F100+F104+F113+F120 -> 57971 | G10: =G11+G21+G32+G53+G78+G100+G104+G113+G120 -> 508 | H10: =H11+H21+H32+H53+H78+H100+H104+H113+H120 -> 30 | I10: =I11+I21+I32+I53+I78+I100+I104+I113+I120 -> 248 | J10: =J11+J21+J32+J53+J78+J100+J104+J113+J120 -> 163 | ... Q10: =Q11+Q21+Q32+Q53+Q78+Q100+Q104+Q113+Q120 -> 1562 | R10: =+E10-SUM(F10:Q10) -> 0 | S10: 88821 | T10: =+S10-F10 -> 30850
A11: 1 | B11: Đảng ủy xã | C11: =+D11+E11 -> 3918 | D11: =D12+D18+D19 -> 0 | E11: =E12+E18+E19+E20 -> 3918 | F11: =F12+F18+F19+F20 -> 0 | G11: =G12+G18+G19+G20 -> 0 | I11: =I12+I18+I19+I20 -> 0 | J11: =J12+J18+J19+J20 -> 0 | K11: =K12+K18+K19+K20 -> 0 | L11: =L12+L18+L19+L20 -> 0 | M11: =M12+M18+M19+M20 -> 0 | N11: =N12+N18+N19+N20 -> 3742 | O11: =O12+O18+O19+O20 -> 0 | P11: =P12+P18+P19+P20 -> 0 | Q11: =Q12+Q18+Q19+Q20 -> 176 | R11: =+E11-SUM(F11:Q11) -> 0 | S11: =+S10-E10 -> 0 | T11: =+E10-F10 -> 30850
A12: 1.1 | B12: Văn phòng Đảng ủy | C12: =+D12+E12 -> 2163 | D12: =SUM(D13:D17) -> 0 | E12: =SUM(E13:E17) -> 2163 | F12: =SUM(F13:F17) -> 0 | G12: =SUM(G13:G17) -> 0 | I12: =SUM(I13:I17) -> 0 | J12: =SUM(J13:J17) -> 0 | K12: =SUM(K13:K17) -> 0 | L12: =SUM(L13:L17) -> 0 | M12: =SUM(M13:M17) -> 0 | N12: =SUM(N13:N17) -> 2163 | O12: =SUM(O13:O17) -> 0 | P12: =SUM(P13:P17) -> 0 | Q12: =SUM(Q13:Q17) -> 0 | R12: =+E12-SUM(F12:Q12) -> 0 | T12: =+T10-T11 -> 0
B13: Chi hoạt động thường xuyên theo định mức(lương, chi khác con người) | C13: =+D13+E13 -> 1607 | E13: =SUM(F13:Q13) -> 1607 | N13: 1607 | R13: =+E13-SUM(F13:Q13) -> 0
B14: Chi hợp đồng 111 (lương, chi khác con người) | C14: =+D14+E14 -> 70 | E14: =SUM(F14:Q14) -> 70 | N14: 70 | R14: =+E14-SUM(F14:Q14) -> 0
B15: Chi phụ cấp Bí thư chi bộ xóm | C15: =+D15+E15 -> 307 | E15: =SUM(F15:Q15) -> 307 | N15: 307 | R15: =+E15-SUM(F15:Q15) -> 0
B16: Chi phụ cấp BCH | C16: =+D16+E16 -> 110 | E16: =SUM(F16:Q16) -> 110 | N16: 110 | R16: =+E16-SUM(F16:Q16) -> 0
B17: Chi cho thành viên ban chỉ đạo 35 | C17: =+D17+E17 -> 69 | E17: =SUM(F17:Q17) -> 69 | N17: 69 | R17: =+E17-SUM(F17:Q17) -> 0
A18: 1.2 | B18: Chi hoạt động chuyên môn của Văn phòng Đảng ủy; Ủy ban kiểm tra; Ban xây dựng đảng (chi các hoạt động của đảng, kinh phí 99...) | C18: =+D18+E18 -> 750 | E18: =SUM(F18:Q18) -> 750 | N18: 750 | R18: =+E18-SUM(F18:Q18) -> 0
A19: 1.3 | B19: Chi Đại hội Đảng bộ xã lần thứ nhất nhiệm kỳ 2025-2030 | C19: =+D19+E19 -> 829 | E19: =SUM(F19:Q19) -> 829 | N19: 829 | R19: =+E19-SUM(F19:Q19) -> 0
A20: 1.4 | B20: Kinh phí tiền thưởng theo Nghị định 73/2024/NĐ-CP | E20: =SUM(F20:Q20) -> 176 | Q20: 176
A21: 2 | B21: Ủy ban Mặt trận Tổ quốc | C21: =SUM(C22:C30) -> 1899 | D21: =SUM(D22:D30) -> 0 | E21: =SUM(E22:E24)+E30+E31 -> 1982 | F21: =SUM(F22:F24)+F30+F31 -> 0 | G21: =SUM(G22:G24)+G30+G31 -> 0 | H21: =SUM(H22:H24)+H30+H31 -> 0 | I21: =SUM(I22:I24)+I30+I31 -> 0 | J21: =SUM(J22:J24)+J30+J31 -> 0 | K21: =SUM(K22:K24)+K30+K31 -> 0 | L21: =SUM(L22:L24)+L30+L31 -> 0 | ... Q21: =SUM(Q22:Q24)+Q30+Q31 -> 83 | R21: =+E21-SUM(F21:Q21) -> 0
A22: 2.1 | B22: Chi hoạt động thường xuyên theo định mức(lương, chi khác con người) | C22: =+D22+E22 -> 837 | E22: =SUM(F22:Q22) -> 837 | N22: 837 | R22: =+E22-SUM(F22:Q22) -> 0
A23: 2.2 | B23: Chi các chế độ ở xóm theo định mức (Tiền phụ cấp, các khoản đóng góp | C23: =+D23+E23 -> 601 | E23: =SUM(F23:Q23) -> 601 | N23: 601 | R23: =+E23-SUM(F23:Q23) -> 0
A24: 2.3 | B24: Kinh phí hoạt động của Ủy ban MTTQ xã: hoạt động chuyên môn (Bao gồm kinh phí tổ chức đại hội) | C24: =+D24+E24 -> 390 | E24: =SUM(F24:Q24) -> 390 | N24: =+SUM(N25:N29) -> 390 | R24: =+E24-SUM(F24:Q24) -> 0
B25: Kinh phí tổ chức đại hội UBMTTQ xã (Bao gồm kinh phí tổ chức đại hội) | E25: =SUM(F25:Q25) -> 150 | N25: 150
B26: Kinh phí hoạt động Đoàn Thanh niên (Bao gồm kinh phí tổ chức đại hội) | E26: =SUM(F26:Q26) -> 60 | N26: 60
B27: Kinh phí hoạt động Hội phụ nữ (Bao gồm kinh phí tổ chức đại hội) | E27: =SUM(F27:Q27) -> 60 | N27: 60
B28: Kinh phí hoạt động Hội Nông dân (Bao gồm kinh phí tổ chức đại hội) | E28: =SUM(F28:Q28) -> 60 | N28: 60
B29: Kinh phí hoạt động Hội Cựu chiến binh (Bao gồm kinh phí tổ chức đại hội) | E29: =SUM(F29:Q29) -> 60 | N29: 60
A30: 2.4 | B30: Kinh phí ban giám sát cộng đồng, thanh tra nhân dân, BCĐ toàn dân đoàn kết | C30: =+D30+E30 -> 71 | E30: =SUM(F30:Q30) -> 71 | N30: =26+45 -> 71 | R30: =+E30-SUM(F30:Q30) -> 0
A31: 2.5 | B31: Kinh phí tiền thưởng theo Nghị định 73/2024/NĐ-CP | E31: =SUM(F31:Q31) -> 83 | Q31: 83
A32: 3 | B32: Văn phòng HĐND và UBND | C32: =SUM(C33:C37)+SUM(C40:C49) -> 12681 | D32: =SUM(D33:D37)+SUM(D40:D49) -> 0 | E32: =+SUM(E33:E37)+SUM(E40:E45)+SUM(E48:E52) -> 11869 | F32: =+SUM(F33:F37)+SUM(F40:F45)+SUM(F48:F52) -> 0 | G32: =+SUM(G33:G37)+SUM(G40:G45)+SUM(G48:G52) -> 171 | H32: =+SUM(H33:H37)+SUM(H40:H45)+SUM(H48:H52) -> 0 | I32: =+SUM(I33:I37)+SUM(I40:I45)+SUM(I48:I52) -> 14 | J32: =+SUM(J33:J37)+SUM(J40:J45)+SUM(J48:J52) -> 93 | K32: =+SUM(K33:K37)+SUM(K40:K45)+SUM(K48:K52) -> 0 | L32: =+SUM(L33:L37)+SUM(L40:L45)+SUM(L48:L52) -> 84 | ... Q32: =+SUM(Q33:Q37)+SUM(Q40:Q45)+SUM(Q48:Q52) -> 110 | R32: =+E32-SUM(F32:Q32) -> 0
A33: 3.1 | B33: Chi hoạt động thường xuyên theo định mức(lương, chi khác con người) | C33: =+D33+E33 -> 1043 | E33: =SUM(F33:Q33) -> 1043 | N33: 1043 | R33: =+E33-SUM(F33:Q33) -> 0
A34: 3.2 | B34: Chi chế độ Thôn đội trưởng | C34: =+D34+E34 -> 202 | E34: =SUM(F34:Q34) -> 202 | O34: 202 | R34: =+E34-SUM(F34:Q34) -> 0
A35: 3.3 | B35: Chi chế độ, phụ cấp tại xóm: Trưởng xóm, phó trưởng xóm,... | C35: =+D35+E35 -> 491 | E35: =SUM(F35:Q35) -> 491 | N35: 491 | R35: =+E35-SUM(F35:Q35) -> 0
A36: 3.4 | B36: Chi chế độ, hoạt động của quân sự (bao gồm hoạt động khám sơ tuyển nghĩa vụ quân sự và các hoạt động chuyên môn khác), hoạt động phòng chống cứu nạn cứu hộ | C36: =+D36+E36 -> 150 | E36: =SUM(F36:Q36) -> 150 | O36: 150 | R36: =+E36-SUM(F36:Q36) -> 0
A37: 3.5 | B37: Chi chế độ, hoạt động của an ninh | C37: =+D37+E37 -> 411 | E37: =SUM(F37:Q37) -> 411 | P37: =+P38+P39 -> 411 | R37: =+E37-SUM(F37:Q37) -> 0
A38: - | B38: Chi tổ bảo vệ ANTT | C38: =+D38+E38 -> 318 | E38: =SUM(F38:Q38) -> 318 | P38: 318 | R38: =+E38-SUM(F38:Q38) -> 0
A39: - | B39: Chi hoạt động chuyên môn (chi hoạt động an ninh, ngày hội toàn dân bảo vệ ANTQ,…) | C39: =+D39+E39 -> 93 | E39: =SUM(F39:Q39) -> 93 | P39: 93 | R39: =+E39-SUM(F39:Q39) -> 0
A40: 3.6 | B40: Chi phụ cấp nhân viên thú y | C40: =+D40+E40 -> 43 | E40: =SUM(F40:Q40) -> 43 | M40: 43 | R40: =+E40-SUM(F40:Q40) -> 0
...

Sheet 05-CTMTQG
AB1: Biểu số 05
A2: DỰ TOÁN CHI CHƯƠNG TRÌNH MỤC TIÊU QUỐC GIA NGÂN SÁCH CẤP TỈNH VÀ NGÂN SÁCH CẤP XÃ NĂM 2025 SAU ĐIỀU CHỈNH
C3: (Kèm theo Nghị quyết số /NQ-HĐND ngày tháng 9 năm 2025 của HĐND xã Quang Sơn)
AA4: ĐVT: Triệu đồng
A5: STT | B5: Đơn vị | C5: STT | D5: Đơn vị | E5: Tổng số | F5: Trong đó | H5: Chương trình mục tiêu quốc gia xây dựng nông thôn mới | O5: Chương trình mục tiêu quốc gia giảm nghèo bền vững | V5: Chương trình mục tiêu quốc gia phát triển kinh tế xã hội vùng đồng bào dân tộc thiểu số và miền núi
F6: Vốn đầu tư | G6: Vốn sự nghiệp | H6: Tổng số | I6: Vốn đầu tư | L6: Vốn sự nghiệp | O6: Tổng số | P6: Vốn đầu tư | S6: Vốn sự nghiệp | V6: Tổng số | W6: Vốn đầu tư | Z6: Vốn sự nghiệp
I7: Tổng số | J7: NSTW | K7: NSĐP đối ứng (tỉnh) | L7: Tổng số | M7: NSTW | N7: NSĐP đối ứng (tỉnh) | P7: Tổng số | Q7: NSTW | R7: NSĐP đối ứng (tỉnh) | S7: Tổng số | T7: NSTW | U7: NSĐP đối ứng (tỉnh) | W7: Tổng số | X7: NSTW | Y7: NSĐP đối ứng (tỉnh) | Z7: Tổng số | AA7: NSTW | AB7: NSĐP đối ứng (tỉnh)
C8: A | D8: B | E8: 1 | F8: 2 | G8: 3 | H8: 4 | I8: 5 | J8: 6 | K8: 7 | L8: 8 | M8: 9 | N8: 10 | O8: 11 | P8: 12 | Q8: 13 | R8: 14 | S8: 15 | T8: 16 | U8: 17 | V8: 18 | W8: 19 | X8: 20 | Y8: 21 | Z8: 22 | AA8: 23 | AB8: 24
D9: =#REF!+#REF!+#REF!+#REF!+#REF!+#REF!+#REF!+#REF!+#REF!+#REF!+#REF!+#REF! -> #REF! | E9: =E10-#REF! -> #REF! | F9: =F10-#REF! -> #REF! | G9: =G10-#REF! -> #REF! | H9: =H10-#REF! -> #REF! | I9: =I10-#REF! -> #REF! | J9: =J10-#REF! -> #REF! | K9: =K10-#REF! -> #REF! | L9: =L10-#REF! -> #REF! | ... AB9: =AB10-#REF! -> #REF!
B10: Tổng cộng | D10: Kiểm tra | E10: =#REF!+#REF!+#REF!+#REF!+#REF!+#REF!+#REF!+#REF!+#REF!+#REF!+#REF!+#REF!+#REF!+#REF!+#REF!+#REF!+#REF!+#REF!+#REF!+#REF!+#REF!+#REF!+#REF!+#REF!+#REF!+#REF!+#REF!+SUM(E11:E11) -> #REF! | F10: =#REF!+#REF!+#REF!+#REF!+#REF!+#REF!+#REF!+#REF!+#REF!+#REF!+#REF!+#REF!+#REF!+#REF!+#REF!+#REF!+#REF!+#REF!+#REF!+#REF!+#REF!+#REF!+#REF!+#REF!+#REF!+#REF!+#REF!+SUM(F11:F11) -> #REF! | G10: =#REF!+#REF!+#REF!+#REF!+#REF!+#REF!+#REF!+#REF!+#REF!+#REF!+#REF!+#REF!+#REF!+#REF!+#REF!+#REF!+#REF!+#REF!+#REF!+#REF!+#REF!+#REF!+#REF!+#REF!+#REF!+#REF!+#REF!+SUM(G11:G11) -> #REF! | H10: =#REF!+#REF!+#REF!+#REF!+#REF!+#REF!+#REF!+#REF!+#REF!+#REF!+#REF!+#REF!+#REF!+#REF!+#REF!+#REF!+#REF!+#REF!+#REF!+#REF!+#REF!+#REF!+#REF!+#REF!+#REF!+#REF!+#REF!+SUM(H11:H11) -> #REF! | I10: =#REF!+#REF!+#REF!+#REF!+#REF!+#REF!+#REF!+#REF!+#REF!+#REF!+#REF!+#REF!+#REF!+#REF!+#REF!+#REF!+#REF!+#REF!+#REF!+#REF!+#REF!+#REF!+#REF!+#REF!+#REF!+#REF!+#REF!+SUM(I11:I11) -> #REF! | J10: =#REF!+#REF!+#REF!+#REF!+#REF!+#REF!+#REF!+#REF!+#REF!+#REF!+#REF!+#REF!+#REF!+#REF!+#REF!+#REF!+#REF!+#REF!+#REF!+#REF!+#REF!+#REF!+#REF!+#REF!+#REF!+#REF!+#REF!+SUM(J11:J11) -> #REF! | K10: =#REF!+#REF!+#REF!+#REF!+#REF!+#REF!+#REF!+#REF!+#REF!+#REF!+#REF!+#REF!+#REF!+#REF!+#REF!+#REF!+#REF!+#REF!+#REF!+#REF!+#REF!+#REF!+#REF!+#REF!+#REF!+#REF!+#REF!+SUM(K11:K11) -> #REF! | L10: =#REF!+#REF!+#REF!+#REF!+#REF!+#REF!+#REF!+#REF!+#REF!+#REF!+#REF!+#REF!+#REF!+#REF!+#REF!+#REF!+#REF!+#REF!+#REF!+#REF!+#REF!+#REF!+#REF!+#REF!+#REF!+#REF!+#REF!+SUM(L11:L11) -> #REF! | ... AB10: =#REF!+#REF!+#REF!+#REF!+#REF!+#REF!+#REF!+#REF!+#REF!+#REF!+#REF!+#REF!+#REF!+#REF!+#REF!+#REF!+#REF!+#REF!+#REF!+#REF!+#REF!+#REF!+#REF!+#REF!+#REF!+#REF!+#REF!+SUM(AB11:AB11) -> #REF!
C11: 1 | D11: Xã Quang Sơn | E11: =F11+G11 -> 17303.06 | F11: =I11+P11+W11 -> 12296.3 | G11: =L11+S11+Z11 -> 5006.76 | H11: =I11+L11 -> 6741.76 | I11: =J11+K11 -> 6588 | J11: 5897 | K11: 691 | L11: =M11+N11 -> 153.76 | M11: 153.76 | O11: =P11+S11 -> 1040 | P11: =Q11+R11 -> 0 | Q11: 0 | R11: 0 | S11: =T11+U11 -> 1040 | T11: 955 | U11: 85 | V11: =W11+Z11 -> 9521.3 | W11: =X11+Y11 -> 5708.3 | X11: 5380.8 | Y11: 327.5 | Z11: =AA11+AB11 -> 3813 | AA11: 3467 | AB11: 346

Sheet 06-Đầu tư tiền đất
W1: Biểu số 06
A2: KẾ HOẠCH ĐẦU TƯ CÔNG NĂM 2025 XÃ QUANG SƠN TỪ NGUỒN TIỀN SỬ DỤNG ĐẤT
A3: =+'01-Cân đôi'!A3:D3 -> (Kèm theo Nghị quyết số /NQ-HĐND ngày tháng 9 năm 2025 của HĐND xã Quang Sơn)
B4: ĐVT: Triệu đồng
A5: Số TT | B5: Danh mục công trình | C5: Tổng mức đầu tư hoặc giá trị quyết toán được duyệt | G5: Lũy kế vốn đã bố trí đến 31/5/2024 (bao gồm cả vốn đề nghị bổ sung lần 3) | K5: Lũy kế khối lượng thực hiện từ khởi công đến 31/5/2024 | O5: Lũy kế giải ngân từ khởi công đến hết ngày 31/5/2024 | S5: Đơn vị thực hiện/ Chủ đầu tư | U5: Thời gian KC-HT | V5: Tổng kế hoạch vốn | W5: Ghi chú
B6: TỔNG CỘNG | H6: =#REF!+#REF!+#REF! -> #REF! | I6: =#REF!+#REF!+#REF! -> #REF! | J6: =#REF!+#REF!+#REF! -> #REF! | K6: =#REF!+#REF!+#REF! -> #REF! | L6: =#REF!+#REF!+#REF! -> #REF! | M6: =#REF!+#REF!+#REF! -> #REF! | N6: =#REF!+#REF!+#REF! -> #REF! | O6: =#REF!+#REF!+#REF! -> #REF! | ... S6: =#REF!+#REF!+#REF! -> #REF! | V6: =+V7+V11+V13 -> 2683 | AH6: =40000-V6 -> 37317 | AI6: =#REF!+AH6 -> #REF! | AJ6: =AI6-#REF! -> #REF! | AK6: 160067 | AL6: =AK6-#REF! -> #REF! | AM6: =AL6-#REF! -> #REF!
A7: I | B7: Giáo dục và đào tạo | V7: =+SUM(V8:V10) -> 2595
A8: 1 | B8: Xây dựng nhà lớp học 2 tầng 8 phòng trường mầm non Tân Long điểm Đồng Mây | T8: Trung tâm Dịch vụ tổng hợp xã Quang Sơn | U8: 2024-2025 | V8: 2380
A9: 2 | B9: Xây dựng nhà hiệu bộ, phòng chức năng, bếp ăn một chiều và các công trình phụ trợ Trường mầm non Tân Long - Điểm trường trung tâm | T9: Trung tâm Dịch vụ tổng hợp xã Quang Sơn | U9: 2024-2025 | V9: 185
A10: 3 | B10: Cải tạo sửa chữa bếp ăn bán trú và mở rộng sân điểm trường Mầm non Lân Đăm, xã Quang Sơn | T10: Trung tâm Dịch vụ tổng hợp xã Quang Sơn | U10: 2025 | V10: 30 | BC10: ok
A11: II | B11: Sự nghiệp kinh tế | V11: =+V12 -> 86
A12: 1 | B12: Điều chỉnh Quy hoạch chung xây dựng xã Tân Long, huyện Đồng Hỷ giai đoạn 2023-2033 | T12: Trung tâm Dịch vụ tổng hợp xã Quang Sơn | U12: 2024-2025 | V12: 86 | BC12: ok
A13: III | B13: Sự nghiệp bảo đảm xã hội | V13: =+V14 -> 2
A14: 2 | B14: Xã Tân Long (Giải quyết tình trạng thiếu nhà ở) | T14: Trung tâm Dịch vụ tổng hợp xã Quang Sơn | U14: 2025 | V14: 2 | BC14: ok

Sheet 07-chuyen nguon
F1: Biểu số 07
A2: BIỂU CHI TIẾT PHÂN BỔ KINH PHÍ TỪ NGUỒN CHUYỂN NGUỒN NGÂN SÁCH NĂM 2024 SANG NĂM 2025
A3: =+'01-Cân đôi'!A3:D3 -> (Kèm theo Nghị quyết số /NQ-HĐND ngày tháng 9 năm 2025 của HĐND xã Quang Sơn)
F4: ĐVT: đồng
A5: TT | B5: Nôị dung | C5: Tổng số | D5: Trong đó | F5: Ghi chú
D6: Vốn đầu tư | E6: Vốn sự nghiệp
B7: TỔNG CỘNG | C7: =+D7+E7 -> 5281044809 | D7: =+D8+D10+D12+D29+D40+D39 -> 3061790660 | E7: =+E8+E10+E12+E29+E40+E39 -> 2219254149
A8: 1 | B8: Chi từ nguồn tăng thu, nguồn khác | C8: =+C9 -> 476000000 | D8: =+D9 -> 476000000 | E8: =+E9 -> 0
B9: Khắc phục hư hỏng đường giao thông phía sau trường tiểu học Sa Lung xã Tân Long | C9: =+SUM(D9:E9) -> 476000000 | D9: 476000000 | F9: cấp huyện chuyển về
A10: 2 | B10: Chi từ nguồn tiền đất | C10: =+C11 -> 73000000 | D10: =+D11 -> 73000000 | E10: =+E11 -> 0
B11: Điều chỉnh quy hoạch chung xây dựng xã Tân Long, huyện Đồng Hỷ giai đoạn 2023-2033 | C11: =+D11+E11 -> 73000000 | D11: 73000000
A12: 3 | B12: Vốn dân tộc thiểu số | C12: =+C13+C28 -> 2948821441 | D12: =+D13+D28 -> 2123312660 | E12: =+E13+E28 -> 825508781
A13: 3.1 | B13: Đầu tư | C13: =+SUM(C14:C27) -> 2123312660 | D13: =+SUM(D14:D27) -> 2123312660 | E13: =+SUM(E14:E27) -> 0
B14: Xây dựng nhà lớp học 2 tầng 8 phòng học Trường Mầm non Tân Long - Điểm Đồng Mây | C14: =+SUM(D14:E14) -> 1799000000 | D14: 1799000000 | F14: cấp huyện chuyển về
B15: Xây dựng nhà văn hoá xóm Lân Đăm, xã Quang Sơn | C15: =+SUM(D15:E15) -> 34300000 | D15: 34300000
B16: Nâng cấp cải tạo đường bê tông xóm Lân Đăm xã Quang Sơn GD3 | C16: =+SUM(D16:E16) -> 55000 | D16: 55000
C17: =+SUM(D17:E17) -> 19545660 | D17: 19545660
B18: Xây dựng cổng, sân, tường rào và các công trình phụ trợ khác nhà văn hóa xóm Làng Giếng xã Tân Long | C18: =+SUM(D18:E18) -> 17100000 | D18: 17100000
B19: Xây dựng cổng, sân, tường rào và các công trình phụ trợ khác nhà văn hóa xóm Đồng Luông xã Tân Long | C19: =+SUM(D19:E19) -> 25400000 | D19: 25400000
B20: Xây dựng cổng, sân, tường rào và các công trình phụ trợ khác nhà văn hóa xóm Ba Đình xã Tân Long | C20: =+SUM(D20:E20) -> 29378000 | D20: 29378000
B21: Xây dựng tường rào trường Tiểu học Sa Lung khu trung tâm xã Tân Long | C21: =+SUM(D21:E21) -> 17534000 | D21: 17534000
B22: Xây dựng cổng, sân, tường rào và các công trình phụ trợ khác nhà văn hóa xóm Đồng Mẫu xã Tân Long | C22: =+SUM(D22:E22) -> 18700000 | D22: 18700000
B23: Xây dựng tường rào, sân, rãnh thoát nước và các công trình phụ trợ khác nhà văn hóa xóm Lân Quan xã Tân Long | C23: =+SUM(D23:E23) -> 62700000 | D23: 62700000
B24: Xây dựng cổng, sân, tường rào và các công trình phụ trợ khác nhà văn hóa xóm Mỏ Ba xã Tân Long | C24: =+SUM(D24:E24) -> 27300000 | D24: 27300000
B25: Xây dựng cổng, sân, tường rào và các công trình phụ trợ khác nhà văn hóa xóm Hồng Phong xã Tân Long | C25: =+SUM(D25:E25) -> 27800000 | D25: 27800000
B26: Xây dựng kè chống sạt lở đường giao thông từ xóm Đồng Mây đi xóm Làng Giếng, xã Tân Long | C26: =+SUM(D26:E26) -> 6700000 | D26: 6700000
B27: Xây dựng cổng, sân, tường rào và các công trình phụ trợ khác nhà văn hóa xóm Đồng Mây xã Tân Long | C27: =+SUM(D27:E27) -> 37800000 | D27: 37800000
A28: 3.2 | B28: Thường xuyên | C28: =+D28+E28 -> 825508781 | E28: 825508781
A29: 4 | B29: Vốn nông thôn mới | C29: =+SUM(D29:E29) -> 389478000 | D29: =+D30 -> 389478000 | E29: =+E30 -> 0
B30: Đầu tư | C30: =+D30+E30 -> 389478000 | D30: =+SUM(D31:D38) -> 389478000 | E30: =+SUM(E31:E38) -> 0
B31: Cải tạo, sửa chữa nền nhà lớp học 2 tầng 8 phòng học và xây mới nhà đa năng trường THCS Quang Sơn | C31: =+SUM(D31:E31) -> 48331000 | D31: 48331000
B32: Xây dựng tường rào, kè chắn đất UBND xã Tân Long | C32: =+SUM(D32:E32) -> 31237000 | D32: 31237000
B33: Xây dựng nhà văn hóa xóm Làng Giếng xã Tân Long | C33: =+SUM(D33:E33) -> 64745000 | D33: 64745000
B34: Nâng cấp sân trung tâm văn hóa thể thao xã Tân Long giai đoạn 2; Hạng mục: Mặt sân, đèn chiếu sáng, rãnh tiêu, thoát nước | C34: =+SUM(D34:E34) -> 87300000 | D34: 87300000
B35: Sửa chữa kênh mương xóm Đồng Luông xã Tân Long | C35: =+SUM(D35:E35) -> 48405000 | D35: 48405000
B36: XD kè đá đoạn cổng trường TH sa Lung, xã Tân Long | C36: =+SUM(D36:E36) -> 33700000 | D36: 33700000
B37: Cải tạo, nâng cấp kênh mương xóm Làng Mới xã Tân Long | C37: =+SUM(D37:E37) -> 43680000 | D37: 43680000
B38: Cải tạo, nâng cấp kênh mương Đồng Sim xóm Ba Đình xã Tân Long | C38: =+SUM(D38:E38) -> 32080000 | D38: 32080000
A39: 5 | B39: Vốn giảm nghèo | C39: =+SUM(D39:E39) -> 195180000 | E39: 195180000
A40: 6 | B40: Kinh phí khác | C40: =+SUM(D40:E40) -> 1198565368 | D40: =+SUM(D41:D43) -> 0 | E40: =+SUM(E41:E43) -> 1198565368
...

Sheet 08-kết dư
F1: Biểu số 08
A2: BIỂU CHI TIẾT PHÂN BỔ KINH PHÍ TỪ NGUỒN KẾT DƯ NGÂN SÁCH NĂM 2024
A3: =+'01-Cân đôi'!A3:D3 -> (Kèm theo Nghị quyết số /NQ-HĐND ngày tháng 9 năm 2025 của HĐND xã Quang Sơn)
F4: ĐVT: đồng
A5: TT | B5: Nôị dung | C5: Tổng số | D5: Trong đó | F5: Ghi chú
D6: Kết dư ngân sách cấp huyện (trước sắp xếp) | E6: Kết dư ngân sách cấp xã (trước sắp xếp)
B7: TỔNG CỘNG | C7: =+D7+E7 -> 4867652963 | D7: =+D8+D10 -> 4491660585 | E7: =+E8+E10 -> 375992378
A8: I | B8: Văn phòng HĐND và UBND | C8: =SUM(C9:C9) -> 364000000 | D8: =SUM(D9:D9) -> 364000000 | E8: =SUM(E9:E9) -> 0
A9: 1 | B9: Chi hỗ trợ đảm bảo cơ sở vật chất để phục vụ mô hình chính quyền 02 cấp | C9: =SUM(D9:E9) -> 364000000 | D9: 364000000 | E9: 0
A10: II | B10: Chưa phân bổ chi tiết | C10: =SUM(C11:C16) -> 4503652963 | D10: =SUM(D11:D16) -> 4127660585 | E10: =SUM(E11:E16) -> 375992378
A11: 1 | B11: Xã Tân Long (cũ) | C11: =SUM(D11:E11) -> 196368799 | D11: 0 | E11: 196368799
A12: 2 | B12: Xã Quang Sơn (cũ) | C12: =SUM(D12:E12) -> 179623579 | D12: 0 | E12: 179623579
A13: 3 | B13: Công tác quy hoạch (nguồn xã hội hóa) | C13: =SUM(D13:E13) -> 223500000 | D13: 223500000
A14: 4 | B14: Chi sự nghiệp kinh tế, môi trường (nguồn phí môi trường) | C14: =SUM(D14:E14) -> 2034160585 | D14: 2034160585 | E14: 0
A15: 5 | B15: Chi sự nghiệp giáo dục | C15: =SUM(D15:E15) -> 1870000000 | D15: 1870000000 | E15: 0

Sheet 09-VT
E1: Biểu số 09
A2: BIỂU CHI TIẾT PHÂN BỔ KẾ HOẠCH VỐN CHI TỪ NGUỒN VIỆN TRỢ, HUY ĐỘNG, ĐÓNG GÓP
A3: =+'01-Cân đôi'!A3:D3 -> (Kèm theo Nghị quyết số /NQ-HĐND ngày tháng 9 năm 2025 của HĐND xã Quang Sơn)
E4: ĐVT: triệu đồng
A5: TT | B5: Nôị dung | C5: Đơn vị thực hiện/ Chủ đầu tư | D5: Tổng số | E5: Ghi chú
A7: 1 | B7: Xây dựng nhà hiệu bộ, phòng chức năng, bếp ăn một chiều và các công trình phụ trợ Trường mầm non Tân Long - Điểm trường trung tâm | C7: Trung tâm Dịch vụ tổng hợp xã Quang Sơn | D7: 3122

Sheet P.b1
U1: Phụ biểu 01
A2: BIỂU CHI TIẾT DỰ TOÁN CHI KINH PHÍ SỰ NGHIỆP GIÁO DỤC- ĐÀO TẠO NĂM 2025 CÁC TRƯỜNG: MẦM NON, TIỂU HỌC, TRUNG HỌC CƠ SỞ TRÊN ĐỊA BÀN XÃ NAM HOÀ
A3: =+'01-Cân đôi'!A3:D3 -> (Kèm theo Nghị quyết số /NQ-HĐND ngày tháng 9 năm 2025 của HĐND xã Quang Sơn)
V4: ĐVT: đ
A5: TT | B5: Đơn vị | C5: Kinh phí chi tự chủ | E5: Kinh phí chi không thường xuyên
C6: Chi lương, phụ cấp lương và các khoản đóng góp, chi hoạt động | D6: Khen thưởng tập thể, cá nhân (QĐ 2269/QĐ-UBND) | E6: Hợp đồng theo Nghị định số 111/2022/NĐ-CP ngày 30/12/2022 của Chính phủ | F6: Chi NC hệ thống thông tin đảm bảo an toàn theo cấp độ | G6: Tiền thưởng theo NĐ 73/NĐ-CP | I6: Các chế độ chính sách
G7: Nguồn sự nghiệp giáo dục | H7: Nguồn CCTL | I7: Kinh phí hỗ trợ theo nghị định số 116/2016/NĐ-CP ngày 18/7/2016 | J7: Kinh phí theo nghị định số 76/2019/NĐ-CP | K7: Kinh phí cấp bù học phí theo NĐ 81/2021/NĐ-CP ngày 27/8/2021 | L7: Kinh phí hỗ trợ chi phí học tập theo NĐ 81/2021/NĐ-CP ngày 27/8/2021 | M7: Kinh phí hỗ trợ học phí theo NQ số 11/2023/NQ-HĐND ngày 20/7/2023 của HĐND tỉnh Thái Nguyên | N7: Kinh phí hỗ trợ ăn trưa cho nhà trẻ theo NQ số 11/2023/NQ-HĐND | O7: Kinh phí hỗ trợ ăn trưa cho trẻ 3,4,5 tuổi theo Nghị định số 105/2020/NĐ-CP | P7: Kinh phí hỗ trợ tăng cường tiếng việt cho trẻ em là người DTTS theo Nghị định số 105/2020/NĐ-CP | Q7: Kinh phí chế độ học sinh khuyết tật theo Thông tư 42/2013/TTLT-BGĐT-BLĐTBXH-BTC | R7: Kinh phí hỗ trợ kinh phí phục vụ nấu ăn cho học sinh theo NĐ 116/2016/NĐ-CP, Nghị quyết số 44/2016/NQ-HĐND | S7: Kinh phí chế độ học sinh bán trú được hỗ trợ theo NĐ 116/2016/NĐ-CP | T7: Kinh phí hỗ trợ giáo viên giảng dạy lớp có học sinh khuyết tật theo Nghị định số 28/2012/NĐ-CP | U7: Kinh phí hỗ trợ học phí cho nhà trẻ, mẫu giáo theo Nghị quyết số 05/2024/NQ-HĐND | V7: Kinh phí hỗ trợ công nhận lại trường chuẩn, kiểm định chất lượng GD, thư viện TT năm 2025
A8: A | B8: B | C8: 1 | D8: 2 | E8: 3 | F8: 4 | G8: 5 | H8: 6 | I8: 7 | J8: 8 | K8: 9 | L8: 10 | M8: 11 | N8: 12 | O8: 13 | P8: 14 | Q8: 15 | R8: 16 | S8: 17 | T8: 18 | U8: 19 | V8: 20
B9: TỔNG CỘNG | C9: =C10+C13+C17 -> 81200000 | D9: =D10+D13+D17 -> 225450000 | E9: =E10+E13+E17 -> 718500000 | F9: =F10+F13+F17 -> 100100000 | G9: =G10+G13+G17 -> 891195000 | H9: =H10+H13+H17 -> 891195000 | I9: =I10+I13+I17 -> 963784000 | J9: =J10+J13+J17 -> 273551850 | ... V9: =V10+V13+V17 -> 80000000 | W9: =+SUM(C9:V9) -> 6144117356
A10: I | B10: Khối Trường Mầm non | C10: =C11+C12 -> 0 | D10: =D11+D12 -> 75460000 | E10: =E11+E12 -> 231300000 | F10: =F11+F12 -> 28600000 | G10: =G11+G12 -> 276068000 | H10: =H11+H12 -> 276068000 | I10: =I11+I12 -> 0 | J10: =J11+J12 -> 64168650 | ... V10: =V11+V12 -> 0 | W10: 6144117356
A11: 1 | B11: MN Tân Long | D11: 46490000 | E11: 72900000 | F11: 14300000 | G11: 176356000 | H11: 176356000 | J11: 64168650 | M11: 1800000 | N11: 67680000 | O11: 403200000 | P11: 44550000 | T11: 56271516 | U11: 19662500 | W11: =+W10-W9 -> 0
A12: 2 | B12: MN Quang Sơn | D12: 28970000 | E12: 158400000 | F12: 14300000 | G12: 99712000 | H12: 99712000 | K12: 14072000 | L12: 2700000 | M12: 2520000 | N12: 14400000 | O12: 57720000 | P12: 4050000 | T12: 24456640 | U12: 22105000
A13: II | B13: Khối Trường Tiểu học | C13: =C14+C15+C16 -> 0 | D13: =D14+D15+D16 -> 92750000 | E13: =E14+E15+E16 -> 487200000 | F13: =F14+F15+F16 -> 42900000 | G13: =G14+G15+G16 -> 381042500 | H13: =H14+H15+H16 -> 381042500 | I13: =I14+I15+I16 -> 0 | J13: =J14+J15+J16 -> 70200000 | ... V13: =V14+V15+V16 -> 0
A14: 1 | B14: TH Tân Long | D14: 30370000 | E14: 243600000 | F14: 14300000 | G14: 118820500 | H14: 118820500 | Q14: 50544000 | S14: 11700000 | T14: 163701854
A15: 2 | B15: TH Quang Sơn | D15: 28970000 | E15: 81200000 | F15: 14300000 | G15: 126876500 | H15: 126876500 | J15: 23400000 | Q15: 16848000 | T15: 45475627
A16: 3 | B16: Tiểu học Sa Lung | D16: 33410000 | E16: 162400000 | F16: 14300000 | G16: 135345500 | H16: 135345500 | J16: 46800000 | Q16: 89856000 | S16: 36270000 | T16: 142368747
A17: III | B17: Khối Trường Trung học cơ sở | C17: =C18+C19 -> 81200000 | D17: =D18+D19 -> 57240000 | E17: =E18+E19 -> 0 | F17: =F18+F19 -> 28600000 | G17: =G18+G19 -> 234084500 | H17: =H18+H19 -> 234084500 | I17: =I18+I19 -> 963784000 | J17: =J18+J19 -> 139183200 | ... V17: =V18+V19 -> 80000000
A18: 1 | B18: THCS Tân Long | C18: 81200000 | D18: 33410000 | F18: 14300000 | G18: 135047500 | H18: 135047500 | I18: 963784000 | J18: 139183200 | Q18: 29696000 | R18: 23400000 | S18: 244764000 | T18: 209864582 | V18: 30000000
A19: 2 | B19: THCS Quang Sơn | D19: 23830000 | F19: 14300000 | G19: 99037000 | H19: 99037000 | Q19: 16848000 | T19: 102617040 | V19: 50000000

Sheet Chi xã
A1: Phụ lục II
A2: SỐ BỔ SUNG TỪ NGÂN SÁCH CẤP TỈNH CHO NGÂN SÁCH XÃ, PHƯỜNG NĂM 2025
A4: STT | B4: Địa phương | C4: TỔNG THU NSNN TRÊN ĐỊA BÀN | D4: Thu ngân sách địa phương | J4: Tổng chi ngân sách cấp xã | K4: Trong đó
D5: Tổng số | E5: Trong đó | K5: Chi từ nguồn thu tiền sử dụng đất | L5: Chi sự nghiệp giáo dục | M5: Dự phòng ngân sách | N5: Chi chuyển nguồn CCTL
E6: Thu NSĐP hưởng theo phân cấp | F6: Bổ sung từ ngân sách cấp tỉnh | I6: Thu chuyển nguồn CCTL
F7: Tổng | G7: Bổ sung cân đối | H7: Bổ sung mục tiêu | L7: Chi sự nghiệp giáo dục | N7: Dự phòng ngân sách
B8: Tổng số | C8: =SUM(C9:C63) -> #REF! | D8: =SUM(D9:D63) -> 5829057.2 | E8: =SUM(E9:E63) -> 137306.36 | F8: =SUM(F9:F63) -> 5633547.8 | G8: =SUM(G9:G63) -> 1126383.9 | H8: =SUM(H9:H63) -> 4507163.9 | I8: =SUM(I9:I63) -> 58203.096 | J8: =SUM(J9:J63) -> 5829057 | ... N8: =SUM(N9:N63) -> 25231.064
A9: 1 | B9: Phường Phan Đình Phùng | C9: =#REF! -> #REF! | D9: =E9+F9+I9 -> 362109.5 | E9: ='[2]Tổng '!D8 -> 16799.656 | F9: =SUM(G9:H9) -> 332634.94 | G9: ='[2]Tổng '!F8 -> 48168.925 | H9: ='[2]Tổng '!G8 -> 284466.02 | I9: ='[2]Tổng '!J8 -> 12674.906 | J9: ='[2]Tổng '!K8 -> 362109.5 | K9: ='[2]Tổng '!R8 -> 0 | L9: ='[2]Tổng '!N8 -> 284466.02 | M9: ='[2]Tổng '!S8 -> 1476.585 | N9: ='[2]Tổng '!T8 -> 3164.223
A10: 2 | B10: Phường Linh Sơn | C10: =#REF! -> #REF! | D10: =E10+F10+I10 -> 173243.08 | E10: ='[2]Tổng '!D9 -> 15823.05 | F10: =SUM(G10:H10) -> 155807.68 | G10: ='[2]Tổng '!F9 -> 30555.393 | H10: ='[2]Tổng '!G9 -> 125252.29 | I10: ='[2]Tổng '!J9 -> 1612.353 | J10: ='[2]Tổng '!K9 -> 173241.87 | K10: ='[2]Tổng '!R9 -> 0 | L10: ='[2]Tổng '!N9 -> 125252.29 | M10: ='[2]Tổng '!S9 -> 950.408 | N10: ='[2]Tổng '!T9 -> 0
A11: 3 | B11: Phường Tích Lương | C11: =#REF! -> #REF! | D11: =E11+F11+I11 -> 196644.31 | E11: ='[2]Tổng '!D10 -> 8485.552 | F11: =SUM(G11:H11) -> 184345.84 | G11: ='[2]Tổng '!F10 -> 35843.045 | H11: ='[2]Tổng '!G10 -> 148502.79 | I11: ='[2]Tổng '!J10 -> 3812.919 | J11: ='[2]Tổng '!K10 -> 196644.31 | K11: ='[2]Tổng '!R10 -> 0 | L11: ='[2]Tổng '!N10 -> 148502.79 | M11: ='[2]Tổng '!S10 -> 954.236 | N11: ='[2]Tổng '!T10 -> 0
A12: 4 | B12: Phường Gia Sàng | C12: =#REF! -> #REF! | D12: =E12+F12+I12 -> 134097.31 | E12: ='[2]Tổng '!D11 -> 6262.504 | F12: =SUM(G12:H12) -> 127746.35 | G12: ='[2]Tổng '!F11 -> 33361.671 | H12: ='[2]Tổng '!G11 -> 94384.681 | I12: ='[2]Tổng '!J11 -> 88.454 | J12: ='[2]Tổng '!K11 -> 134096.93 | K12: ='[2]Tổng '!R11 -> 0 | L12: ='[2]Tổng '!N11 -> 94384.681 | M12: ='[2]Tổng '!S11 -> 786.665 | N12: ='[2]Tổng '!T11 -> 0
A13: 5 | B13: Phường Quyết Thắng | C13: =#REF! -> #REF! | D13: =E13+F13+I13 -> 96246.388 | E13: ='[2]Tổng '!D12 -> 4524.46 | F13: =SUM(G13:H13) -> 73149.225 | G13: ='[2]Tổng '!F12 -> 14899.018 | H13: ='[2]Tổng '!G12 -> 58250.207 | I13: ='[2]Tổng '!J12 -> 18572.703 | J13: ='[2]Tổng '!K12 -> 96246.388 | K13: ='[2]Tổng '!R12 -> 0 | L13: ='[2]Tổng '!N12 -> 58250.207 | M13: ='[2]Tổng '!S12 -> 517.239 | N13: ='[2]Tổng '!T12 -> 11923.982
A14: 6 | B14: Phường Quan Triều | C14: =#REF! -> #REF! | D14: =E14+F14+I14 -> 140699.11 | E14: ='[2]Tổng '!D13 -> 8533.996 | F14: =SUM(G14:H14) -> 128841.65 | G14: ='[2]Tổng '!F13 -> 25823.682 | H14: ='[2]Tổng '!G13 -> 103017.97 | I14: ='[2]Tổng '!J13 -> 3323.46 | J14: ='[2]Tổng '!K13 -> 140699.11 | K14: ='[2]Tổng '!R13 -> 0 | L14: ='[2]Tổng '!N13 -> 103017.97 | M14: ='[2]Tổng '!S13 -> 746.747 | N14: ='[2]Tổng '!T13 -> 0
A15: 7 | B15: Xã Tân Cương | C15: =#REF! -> #REF! | D15: =E15+F15+I15 -> 88286.514 | E15: ='[2]Tổng '!D14 -> 5091.552 | F15: =SUM(G15:H15) -> 79767.741 | G15: ='[2]Tổng '!F14 -> 20457 | H15: ='[2]Tổng '!G14 -> 59310.741 | I15: ='[2]Tổng '!J14 -> 3427.221 | J15: ='[2]Tổng '!K14 -> 88287.514 | K15: ='[2]Tổng '!R14 -> 0 | L15: ='[2]Tổng '!N14 -> 59310.741 | M15: ='[2]Tổng '!S14 -> 574.137 | N15: ='[2]Tổng '!T14 -> 0
A16: 8 | B16: Xã Đại Phúc | C16: =#REF! -> #REF! | D16: =E16+F16+I16 -> 182952.77 | E16: ='[2]Tổng '!D15 -> 10764.008 | F16: =SUM(G16:H16) -> 167619.37 | G16: ='[2]Tổng '!F15 -> 23095.536 | H16: ='[2]Tổng '!G15 -> 144523.84 | I16: ='[2]Tổng '!J15 -> 4569.386 | J16: ='[2]Tổng '!K15 -> 182952.77 | K16: ='[2]Tổng '!R15 -> 0 | L16: ='[2]Tổng '!N15 -> 138869.84 | M16: ='[2]Tổng '!S15 -> 755.515 | N16: ='[2]Tổng '!T15 -> 20.609
A17: 9 | B17: Xã Đại Từ | C17: =#REF! -> #REF! | D17: =E17+F17+I17 -> 107914.5 | E17: ='[2]Tổng '!D16 -> 891 | F17: =SUM(G17:H17) -> 107023.5 | G17: ='[2]Tổng '!F16 -> 22609 | H17: ='[2]Tổng '!G16 -> 84414.5 | I17: ='[2]Tổng '!J16 -> 0 | J17: ='[2]Tổng '!K16 -> 107914.5 | K17: ='[2]Tổng '!R16 -> 0 | L17: ='[2]Tổng '!N16 -> 70493.5 | M17: ='[2]Tổng '!S16 -> 507 | N17: ='[2]Tổng '!T16 -> 0
A18: 10 | B18: Xã Đức Lương | C18: =#REF! -> #REF! | D18: =E18+F18+I18 -> 59716.3 | E18: ='[2]Tổng '!D17 -> 272 | F18: =SUM(G18:H18) -> 59444.3 | G18: ='[2]Tổng '!F17 -> 14332 | H18: ='[2]Tổng '!G17 -> 45112.3 | I18: ='[2]Tổng '!J17 -> 0 | J18: ='[2]Tổng '!K17 -> 59716.3 | K18: ='[2]Tổng '!R17 -> 0 | L18: ='[2]Tổng '!N17 -> 36303.3 | M18: ='[2]Tổng '!S17 -> 320 | N18: ='[2]Tổng '!T17 -> 0
A19: 11 | B19: Xã Phú Thịnh | C19: =#REF! -> #REF! | D19: =E19+F19+I19 -> 82372.8 | E19: ='[2]Tổng '!D18 -> 737 | F19: =SUM(G19:H19) -> 81635.8 | G19: ='[2]Tổng '!F18 -> 16481 | H19: ='[2]Tổng '!G18 -> 65154.8 | I19: ='[2]Tổng '!J18 -> 0 | J19: ='[2]Tổng '!K18 -> 82372.8 | K19: ='[2]Tổng '!R18 -> 0 | L19: ='[2]Tổng '!N18 -> 54629.8 | M19: ='[2]Tổng '!S18 -> 379 | N19: ='[2]Tổng '!T18 -> 0
A20: 12 | B20: Xã La Bằng | C20: =#REF! -> #REF! | D20: =E20+F20+I20 -> 78203 | E20: ='[2]Tổng '!D19 -> 1588 | F20: =SUM(G20:H20) -> 76615 | G20: ='[2]Tổng '!F19 -> 14700 | H20: ='[2]Tổng '!G19 -> 61915 | I20: ='[2]Tổng '!J19 -> 0 | J20: ='[2]Tổng '!K19 -> 78203 | K20: ='[2]Tổng '!R19 -> 0 | L20: ='[2]Tổng '!N19 -> 52223 | M20: ='[2]Tổng '!S19 -> 363 | N20: ='[2]Tổng '!T19 -> 0
... A63: 55 | B63: Xã Sảng Mộc | C63: =#REF! -> #REF! | D63: =E63+F63+I63 -> 41486.482 | E63: ='[2]Tổng '!D62 -> 52 | F63: =SUM(G63:H63) -> 41434.482 | G63: ='[2]Tổng '!F62 -> 5191 | H63: ='[2]Tổng '!G62 -> 36243.482 | I63: ='[2]Tổng '!J62 -> 0 | J63: ='[2]Tổng '!K62 -> 41486.482 | K63: ='[2]Tổng '!R62 -> 0 | L63: ='[2]Tổng '!N62 -> 33022.482 | M63: ='[2]Tổng '!S62 -> 109 | N63: ='[2]Tổng '!T62 -> 0

Sheet Sheet3
A1: STT | B1: Nội dung | C1: Dự toán năm 2025 | D1: Dự toán năm 2025 sau sắp xếp | E1: Chênh lệch
A2: 1 | B2: Tổng thu ngân sách nhà nước trên địa bàn | C2: =#REF! -> #REF! | D2: =#REF! -> #REF! | E2: =C2-D2 -> #REF!
A3: 2 | B3: Thu NSĐP hưởng theo phân cấp | C3: ='Chi xã'!E8 -> 137306.36 | D3: ='Chi xã'!E8 -> 137306.36 | E3: =C3-D3 -> 0
A4: 3 | B4: Số bổ sung cân đối | C4: ='Chi xã'!G8 -> 1126383.9 | D4: =C4 -> 1126383.9 | E4: =C4-D4 -> 0
A5: 4 | B5: Số bổ sung có mục tiêu | C5: ='[2]Tổng '!$I$7+3 -> 269232.66 | D5: =Chi!H9 -> 269229.66 | E5: =D5-C5 -> -3
A6: 5 | B6: Số thu chuyển nguồn CCTL | C6: ='Chi xã'!I8 -> 58203.096 | D6: =C6 -> 58203.096 | E6: =D6-C6 -> 0
A7: 6 | B7: Tổng chi ngân sách địa phương | C7: ='Chi xã'!J8-'Chi xã'!L8 -> 1591125.7 | D7: =Chi!J9 -> 1591125.7 | E7: =D7-C7 -> 0

Sheet Chi
A1: Phụ lục II
A2: SỐ BỔ SUNG TỪ NGÂN SÁCH CẤP TỈNH CHO NGÂN SÁCH XÃ, PHƯỜNG NĂM 2025
K4: ĐVT: Triệu đồng
A5: STT | B5: Địa phương | C5: TỔNG THU NSNN TRÊN ĐỊA BÀN | D5: Thu ngân sách địa phương | J5: Tổng chi ngân sách cấp xã
D6: Tổng số | E6: Trong đó | J6: Tổng số (*) | K6: Trong đó
E7: Thu NSĐP hưởng theo phân cấp | F7: Bổ sung từ ngân sách tỉnh | I7: Thu chuyển nguồn CCTL | K7: Chi nguyên trạng xã | L7: Chi từ nguồn thu tiền sử dụng đất | M7: Dự phòng ngân sách | N7: Chi chuyển nguồn CCTL
F8: Tổng | G8: Bổ sung cân đối | H8: Bổ sung mục tiêu (nguyên trạng xã) | N8: Dự phòng ngân sách
B9: Tổng số | C9: =C10+C18+C24+C30+C35+C39+C44+C48+C54+C59+C63+C67+C71+C75+C79+C82+C85+C88+C93+C98+C103+C107+C110+C116+C120+C125+C131+C135+C140+C143+C146+C149+C152+C155+C159+C163+C167+C172+C177+C181+C185+C190+C195+C199+C203+C206+C209+C212+C215+C219+C223+C226+C229+C232+C235 -> #REF! | D9: =D10+D18+D24+D30+D35+D39+D44+D48+D54+D59+D63+D67+D71+D75+D79+D82+D85+D88+D93+D98+D103+D107+D110+D116+D120+D125+D131+D135+D140+D143+D146+D149+D152+D155+D159+D163+D167+D172+D177+D181+D185+D190+D195+D199+D203+D206+D209+D212+D215+D219+D223+D226+D229+D232+D235+3 -> 1591126 | E9: =E10+E18+E24+E30+E35+E39+E44+E48+E54+E59+E63+E67+E71+E75+E79+E82+E85+E88+E93+E98+E103+E107+E110+E116+E120+E125+E131+E135+E140+E143+E146+E149+E152+E155+E159+E163+E167+E172+E177+E181+E185+E190+E195+E199+E203+E206+E209+E212+E215+E219+E223+E226+E229+E232+E235 -> 137306.36 | F9: =F10+F18+F24+F30+F35+F39+F44+F48+F54+F59+F63+F67+F71+F75+F79+F82+F85+F88+F93+F98+F103+F107+F110+F116+F120+F125+F131+F135+F140+F143+F146+F149+F152+F155+F159+F163+F167+F172+F177+F181+F185+F190+F195+F199+F203+F206+F209+F212+F215+F219+F223+F226+F229+F232+F235 -> 1395613.5 | G9: =G10+G18+G24+G30+G35+G39+G44+G48+G54+G59+G63+G67+G71+G75+G79+G82+G85+G88+G93+G98+G103+G107+G110+G116+G120+G125+G131+G135+G140+G143+G146+G149+G152+G155+G159+G163+G167+G172+G177+G181+G185+G190+G195+G199+G203+G206+G209+G212+G215+G219+G223+G226+G229+G232+G235 -> 1126383.9 | H9: =H10+H18+H24+H30+H35+H39+H44+H48+H54+H59+H63+H67+H71+H75+H79+H82+H85+H88+H93+H98+H103+H107+H110+H116+H120+H125+H131+H135+H140+H143+H146+H149+H152+H155+H159+H163+H167+H172+H177+H181+H185+H190+H195+H199+H203+H206+H209+H212+H215+H219+H223+H226+H229+H232+H235 -> 269229.66 | I9: =I10+I18+I24+I30+I35+I39+I44+I48+I54+I59+I63+I67+I71+I75+I79+I82+I85+I88+I93+I98+I103+I107+I110+I116+I120+I125+I131+I135+I140+I143+I146+I149+I152+I155+I159+I163+I167+I172+I177+I181+I185+I190+I195+I199+I203+I206+I209+I212+I215+I219+I223+I226+I229+I232+I235 -> 58203.096 | J9: =J10+J18+J24+J30+J35+J39+J44+J48+J54+J59+J63+J67+J71+J75+J79+J82+J85+J88+J93+J98+J103+J107+J110+J116+J120+J125+J131+J135+J140+J143+J146+J149+J152+J155+J159+J163+J167+J172+J177+J181+J185+J190+J195+J199+J203+J206+J209+J212+J215+J219+J223+J226+J229+J232+J235 -> 1591125.7 | K9: =K10+K18+K24+K30+K35+K39+K44+K48+K54+K59+K63+K67+K71+K75+K79+K82+K85+K88+K93+K98+K103+K107+K110+K116+K120+K125+K131+K135+K140+K143+K146+K149+K152+K155+K159+K163+K167+K172+K177+K181+K185+K190+K195+K199+K203+K206+K209+K212+K215+K219+K223+K226+K229+K232+K235 -> 1533402.4 | L9: =L10+L18+L24+L30+L35+L39+L44+L48+L54+L59+L63+L67+L71+L75+L79+L82+L85+L88+L93+L98+L103+L107+L110+L116+L120+L125+L131+L135+L140+L143+L146+L149+L152+L155+L159+L163+L167+L172+L177+L181+L185+L190+L195+L199+L203+L206+L209+L212+L215+L219+L223+L226+L229+L232+L235 -> 6932 | ... N9: =N10+N18+N24+N30+N35+N39+N44+N48+N54+N59+N63+N67+N71+N75+N79+N82+N85+N88+N93+N98+N103+N107+N110+N116+N120+N125+N131+N135+N140+N143+N146+N149+N152+N155+N159+N163+N167+N172+N177+N181+N185+N190+N195+N199+N203+N206+N209+N212+N215+N219+N223+N226+N229+N232+N235 -> 25231.064 | O9: =D9-J9 -> 0.258
A10: 1 | B10: Phường Phan Đình Phùng | C10: =SUM(C11:C17) -> 144798 | D10: =E10+F10+I10 -> 77643.487 | E10: =SUM(E11:E17) -> 16799.656 | F10: =SUM(F11:F17) -> 48168.925 | G10: =SUM(G11:G17) -> 48168.925 | H10: =SUM(H11:H17) -> 0 | I10: =SUM(I11:I17) -> 12674.906 | J10: =SUM(K10:N10) -> 77643.487 | K10: =SUM(K11:K17) -> 73002.679 | L10: ='[2]Tổng '!R8 -> 0 | M10: =SUM(M11:M17) -> 1476.585 | N10: =SUM(N11:N17) -> 3164.223
B11: Hoàng Văn Thụ | C11: 28763 | D11: =E11+F11+I11 -> 11451.487 | E11: ='[2]Thu '!D9 -> 2671.996 | F11: =SUM(G11:H11) -> 8779.491 | G11: ='[2]Thu '!E9 -> 8779.491 | H11: ='[2]Thu '!F9 -> 0 | J11: =SUM(K11:N11) -> 11489.719 | K11: =[2]TPTN!$I$16+[2]TPTN!$I$11 -> 11262.306 | M11: =[2]TPTN!$I$31 -> 227.413 | N11: =[2]TPTN!$I$33 -> 0
B12: Phan Đình Phùng | C12: 31077 | D12: =E12+F12+I12 -> 14785.307 | E12: ='[2]Thu '!D4 -> 2955.456 | F12: =SUM(G12:H12) -> 11813.65 | G12: ='[2]Thu '!E4 -> 11813.65 | H12: ='[2]Thu '!F4 -> 0 | I12: 16.201 | J12: =SUM(K12:N12) -> 14769.106 | K12: =[2]TPTN!$D$16 -> 14476.007 | M12: =[2]TPTN!$D$31 -> 293.099 | N12: =[2]TPTN!$D$33 -> 0
B13: Quang Trung | C13: 21166 | D13: =E13+F13+I13 -> 19513.458 | E13: ='[2]Thu '!D8 -> 2150.06 | F13: =SUM(G13:H13) -> 9044.985 | G13: ='[2]Thu '!E8 -> 9044.985 | H13: ='[2]Thu '!F8 -> 0 | I13: 8318.413 | J13: =SUM(K13:N13) -> 11195.045 | K13: =[2]TPTN!$H$16 -> 10973.01 | M13: =[2]TPTN!$H$31 -> 222.035 | N13: =[2]TPTN!$H$33 -> 0
B14: Trưng Vương | C14: 18137 | D14: =E14+F14+I14 -> 10901.66 | E14: ='[2]Thu '!D5 -> 2024.936 | F14: =SUM(G14:H14) -> 6618.939 | G14: ='[2]Thu '!E5 -> 6618.939 | H14: ='[2]Thu '!F5 -> 0 | I14: 2257.785 | J14: =SUM(K14:N14) -> 8660.076 | K14: =[2]TPTN!$E$16 -> 8488.105 | M14: =[2]TPTN!$E$31 -> 171.971 | N14: =[2]TPTN!$E$33 -> 0
B15: Đồng Quang | C15: 17118 | D15: =E15+F15+I15 -> 7051.96 | E15: ='[2]Thu '!D7 -> 1674.244 | F15: =SUM(G15:H15) -> 5377.716 | G15: ='[2]Thu '!E7 -> 5377.716 | H15: ='[2]Thu '!F7 -> 0 | J15: =SUM(K15:N15) -> 9309.745 | K15: =[2]TPTN!$G$16 -> 9125.195 | M15: =[2]TPTN!$G$31 -> 184.55 | N15: =[2]TPTN!$G$33 -> 0
B16: Túc Duyên | C16: 17304 | D16: =E16+F16+I16 -> 4417.925 | E16: ='[2]Thu '!D6 -> 1718.38 | F16: =SUM(G16:H16) -> 2661.313 | G16: ='[2]Thu '!E6 -> 2661.313 | H16: ='[2]Thu '!F6 -> 0 | I16: 38.232 | J16: =SUM(K16:N16) -> 12698.106 | K16: =[2]TPTN!$F$16 -> 9345.068 | M16: =[2]TPTN!$F$31 -> 188.815 | N16: =[2]TPTN!$F$33 -> 3164.223
B17: Tân Thịnh | C17: 11233 | D17: =E17+F17+I17 -> 9521.69 | E17: ='[2]Thu '!D10 -> 3604.584 | F17: =SUM(G17:H17) -> 3872.831 | G17: ='[2]Thu '!E10 -> 3872.831 | H17: ='[2]Thu '!F10 -> 0 | I17: 2044.275 | J17: =SUM(K17:N17) -> 9521.69 | K17: =[2]TPTN!$J$16 -> 9332.988 | M17: =[2]TPTN!$J$31 -> 188.702 | N17: =[2]TPTN!$J$33 -> 0
A18: 2 | B18: Phường Linh Sơn | C18: =SUM(C19:C23) -> 29400 | D18: =E18+F18+I18 -> 47990.796 | E18: =SUM(E19:E23) -> 15823.05 | F18: =SUM(G18:H18) -> 30555.393 | G18: =SUM(G19:G23) -> 30555.393 | H18: =SUM(H19:H23) -> 0 | I18: =SUM(I19:I23) -> 1612.353 | J18: =SUM(K18:N18) -> 47989.586 | K18: =SUM(K19:K23) -> 47039.178 | L18: ='[2]Tổng '!R9 -> 0 | M18: =SUM(M19:M23) -> 950.408 | N18: =SUM(N19:N23) -> 0
B19: Chùa Hang | C19: 9730 | D19: =E19+F19+I19 -> 9400.324 | E19: ='[2]Thu '!D11 -> 2908.554 | F19: =SUM(G19:H19) -> 6491.77 | G19: ='[2]Thu '!E11 -> 6491.77 | H19: ='[2]Thu '!F11 -> 0 | I19: ='[2]Thu '!G11 -> 0 | J19: =SUM(K19:N19) -> 9399.864 | K19: =[2]TPTN!$K$16 -> 9213.811 | M19: =[2]TPTN!$K$31 -> 186.053
B20: Cao Ngạn | C20: 6279 | D20: =E20+F20+I20 -> 9837.488 | E20: ='[2]Thu '!D12 -> 5851.92 | F20: =SUM(G20:H20) -> 3953.816 | G20: ='[2]Thu '!E12 -> 3953.816 | H20: ='[2]Thu '!F12 -> 0 | I20: ='[2]Thu '!G12 -> 31.752 | J20: =SUM(K20:N20) -> 9836.738 | K20: =[2]TPTN!$L$16 -> 9642 | M20: =[2]TPTN!$L$31 -> 194.738
B21: Đồng Bẩm | C21: 8845 | D21: =E21+F21+I21 -> 8896.69 | E21: ='[2]Thu '!D13 -> 3044.376 | F21: =SUM(G21:H21) -> 4334.569 | G21: ='[2]Thu '!E13 -> 4334.569 | H21: ='[2]Thu '!F13 -> 0 | I21: ='[2]Thu '!G13 -> 1517.745 | J21: =SUM(K21:N21) -> 8896.69 | K21: =[2]TPTN!$M$16 -> 8719.961 | M21: =[2]TPTN!$M$31 -> 176.729
B22: Linh Sơn | C22: 1486 | D22: =E22+F22+I22 -> 9999.087 | E22: ='[2]Thu '!D14 -> 1283.12 | F22: =SUM(G22:H22) -> 8680.651 | G22: ='[2]Thu '!E14 -> 8680.651 | H22: ='[2]Thu '!F14 -> 0 | I22: ='[2]Thu '!G14 -> 35.316 | J22: =SUM(K22:N22) -> 9999.087 | K22: =[2]TPTN!$N$16 -> 9801.165 | M22: =[2]TPTN!$N$31 -> 197.922
B23: Huống Thượng | C23: 3060 | D23: =E23+F23+I23 -> 9857.207 | E23: ='[2]Thu '!D15 -> 2735.08 | F23: =SUM(G23:H23) -> 7094.587 | G23: ='[2]Thu '!E15 -> 7094.587 | H23: ='[2]Thu '!F15 -> 0 | I23: ='[2]Thu '!G15 -> 27.54 | J23: =SUM(K23:N23) -> 9857.207 | K23: =[2]TPTN!$O$16 -> 9662.241 | M23: =[2]TPTN!$O$31 -> 194.966
A24: 3 | B24: Phường Tích Lương | C24: =SUM(C25:C29) -> 40670 | D24: =E24+F24+I24 -> 48141.516 | E24: =SUM(E25:E29) -> 8485.552 | F24: =SUM(G24:H24) -> 35843.045 | G24: =SUM(G25:G29) -> 35843.045 | H24: =SUM(H25:H29) -> 0 | I24: =SUM(I25:I29) -> 3812.919 | J24: =SUM(K24:N24) -> 48141.516 | K24: =SUM(K25:K29) -> 47187.28 | L24: ='[2]Tổng '!R10 -> 0 | M24: =SUM(M25:M29) -> 954.236 | N24: ='[2]Tổng '!T10 -> 0
B25: Phú Xá | C25: 4786 | D25: =E25+F25+I25 -> 9851.471 | E25: ='[2]Thu '!D16 -> 1770.772 | F25: =SUM(G25:H25) -> 7794.745 | G25: ='[2]Thu '!E16 -> 7794.745 | H25: ='[2]Thu '!F16 -> 0 | I25: ='[2]Thu '!G16 -> 285.954 | J25: =SUM(K25:N25) -> 9851.471 | K25: =[2]TPTN!$P$16 -> 9656.274 | M25: =[2]TPTN!$P$31 -> 195.197
B26: Trung Thành | C26: 9789 | D26: =E26+F26+I26 -> 10410.965 | E26: ='[2]Thu '!D17 -> 2734.904 | F26: =SUM(G26:H26) -> 7642.04 | G26: ='[2]Thu '!E17 -> 7642.04 | H26: ='[2]Thu '!F17 -> 0 | I26: ='[2]Thu '!G17 -> 34.021 | J26: =SUM(K26:N26) -> 10410.965 | K26: =[2]TPTN!$R$16 -> 10204.553 | M26: =[2]TPTN!$R$31 -> 206.412
B27: Tân Thành | C27: 1548 | D27: =E27+F27+I27 -> 7722.295 | E27: ='[2]Thu '!D18 -> 579.24 | F27: =SUM(G27:H27) -> 7143.055 | G27: ='[2]Thu '!E18 -> 7143.055 | H27: ='[2]Thu '!F18 -> 0 | I27: ='[2]Thu '!G18 -> 0 | J27: =SUM(K27:N27) -> 7722.295 | K27: =[2]TPTN!$Q$16 -> 7569.01 | M27: =[2]TPTN!$Q$31 -> 153.285
B28: Tân Lập | C28: 20874 | D28: =E28+F28+I28 -> 9600.532 | E28: ='[2]Thu '!D19 -> 2038.992 | F28: =SUM(G28:H28) -> 4101.969 | G28: ='[2]Thu '!E19 -> 4101.969 | H28: ='[2]Thu '!F19 -> 0 | I28: ='[2]Thu '!G19 -> 3459.571 | J28: =SUM(K28:N28) -> 9600.532 | K28: =[2]TPTN!$S$16 -> 9410.295 | M28: =[2]TPTN!$S$31 -> 190.237
B29: Tích Lương | C29: 3673 | D29: =E29+F29+I29 -> 10556.253 | E29: ='[2]Thu '!D20 -> 1361.644 | F29: =SUM(G29:H29) -> 9161.236 | G29: ='[2]Thu '!E20 -> 9161.236 | H29: ='[2]Thu '!F20 -> 0 | I29: ='[2]Thu '!G20 -> 33.373 | J29: =SUM(K29:N29) -> 10556.253 | K29: =[2]TPTN!$T$16 -> 10347.148 | M29: =[2]TPTN!$T$31 -> 209.105
A30: 4 | B30: Phường Gia Sàng | C30: =C31+C32+C33+C34 -> 33914 | D30: =E30+F30+I30 -> 39712.629 | E30: =E31+E32+E33+E34 -> 6262.504 | F30: =SUM(G30:H30) -> 33361.671 | G30: =G31+G32+G33+G34 -> 33361.671 | H30: =H31+H32+H33+H34 -> 0 | I30: =I31+I32+I33+I34 -> 88.454 | J30: =SUM(K30:N30) -> 39712.245 | K30: =K31+K32+K33+K34 -> 38925.58 | L30: ='[2]Tổng '!R11 -> 0 | M30: =SUM(M31:M34) -> 786.665 | N30: ='[2]Tổng '!T11 -> 0
B31: Hương Sơn | C31: 7885 | D31: =E31+F31+I31 -> 10955.339 | E31: ='[2]Thu '!D21 -> 2110.192 | F31: =SUM(G31:H31) -> 8809.507 | G31: ='[2]Thu '!E21 -> 8809.507 | H31: ='[2]Thu '!F21 -> 0 | I31: ='[2]Thu '!G21 -> 35.64 | J31: =SUM(K31:N31) -> 10954.956 | K31: =[2]TPTN!$U$16 -> 10738 | M31: =[2]TPTN!$U$31 -> 216.956
B32: Đồng Liên | C32: 658 | D32: =E32+F32+I32 -> 8572.281 | E32: ='[2]Thu '!D22 -> 521.744 | F32: =SUM(G32:H32) -> 8027.208 | G32: ='[2]Thu '!E22 -> 8027.208 | H32: ='[2]Thu '!F22 -> 0 | I32: ='[2]Thu '!G22 -> 23.329 | J32: =SUM(K32:N32) -> 8572.281 | K32: =[2]TPTN!$V$16 -> 8402.391 | M32: =[2]TPTN!$V$31 -> 169.89
B33: Cam Giá | C33: 4944 | D33: =E33+F33+I33 -> 9923.341 | E33: ='[2]Thu '!D23 -> 1642.748 | F33: =SUM(G33:H33) -> 8251.108 | G33: ='[2]Thu '!E23 -> 8251.108 | H33: ='[2]Thu '!F23 -> 0 | I33: ='[2]Thu '!G23 -> 29.485 | J33: =SUM(K33:N33) -> 9923.341 | K33: =[2]TPTN!$W$16 -> 9726.786 | M33: =[2]TPTN!$W$31 -> 196.555
B34: Gia Sàng | C34: 20427 | D34: =E34+F34+I34 -> 10261.668 | E34: ='[2]Thu '!D24 -> 1987.82 | F34: =SUM(G34:H34) -> 8273.848 | G34: ='[2]Thu '!E24 -> 8273.848 | H34: ='[2]Thu '!F24 -> 0 | I34: ='[2]Thu '!G24 -> 0 | J34: =SUM(K34:N34) -> 10261.667 | K34: =[2]TPTN!$X$16 -> 10058.403 | M34: =[2]TPTN!$X$31 -> 203.264
A35: 5 | B35: Phường Quyết Thắng | C35: =SUM(C36:C38) -> 26871 | D35: =E35+F35+I35 -> 37996.181 | E35: =SUM(E36:E38) -> 4524.46 | F35: =SUM(G35:H35) -> 14899.018 | G35: =SUM(G36:G38) -> 14899.018 | H35: =SUM(H36:H38) -> 0 | I35: =SUM(I36:I38) -> 18572.703 | J35: =SUM(K35:N35) -> 37996.181 | K35: =SUM(K36:K38) -> 25554.96 | L35: ='[2]Tổng '!R12 -> 0 | M35: =SUM(M36:M38) -> 517.239 | N35: =SUM(N36:N38) -> 11923.982
B36: Thịnh Đán | C36: 16359 | D36: =E36+F36+I36 -> 9388.71 | E36: ='[2]Thu '!D25 -> 1711.812 | F36: =SUM(G36:H36) -> 5925.902 | G36: ='[2]Thu '!E25 -> 5925.902 | H36: ='[2]Thu '!F25 -> 0 | I36: ='[2]Thu '!G25 -> 1750.996 | J36: =SUM(K36:N36) -> 9388.71 | K36: =[2]TPTN!$Y$16 -> 9202.417 | M36: =[2]TPTN!$Y$31 -> 186.293 | N36: =[2]TPTN!$Y$33 -> 0
B37: Quyết Thắng | C37: 9706 | D37: =E37+F37+I37 -> 21111.517 | E37: ='[2]Thu '!D26 -> 2073.448 | F37: =SUM(G37:H37) -> 2273.991 | G37: ='[2]Thu '!E26 -> 2273.991 | H37: ='[2]Thu '!F26 -> 0 | I37: ='[2]Thu '!G26 -> 16764.078 | J37: =SUM(K37:N37) -> 21111.517 | K37: =[2]TPTN!$Z$16 -> 9005.369 | M37: =[2]TPTN!$Z$31 -> 182.166 | N37: =[2]TPTN!$Z$33 -> 11923.982
B38: Phúc Hà | C38: 806 | D38: =E38+F38+I38 -> 7495.954 | E38: ='[2]Thu '!D27 -> 739.2 | F38: =SUM(G38:H38) -> 6699.125 | G38: ='[2]Thu '!E27 -> 6699.125 | H38: ='[2]Thu '!F27 -> 0 | I38: ='[2]Thu '!G27 -> 57.629 | J38: =SUM(K38:N38) -> 7495.954 | K38: =[2]TPTN!$AA$16 -> 7347.174 | M38: =[2]TPTN!$AA$31 -> 148.78 | N38: =[2]TPTN!$AA$33 -> 0
A39: 6 | B39: Phường Quan Triều | C39: =SUM(C40:C43) -> 20404 | D39: =E39+F39+I39 -> 37681.138 | E39: =SUM(E40:E43) -> 8533.996 | F39: =SUM(G39:H39) -> 25823.682 | G39: =SUM(G40:G43) -> 25823.682 | H39: =SUM(H40:H43) -> 0 | I39: =SUM(I40:I43) -> 3323.46 | J39: =SUM(K39:N39) -> 37681.138 | K39: =SUM(K40:K43) -> 36934.391 | L39: ='[2]Tổng '!R13 -> 0 | M39: =SUM(M40:M43) -> 746.747 | N39: =SUM(N40:N43) -> 0
B40: Tân Long | C40: 3987 | D40: =E40+F40+I40 -> 8491.646 | E40: ='[2]Thu '!D28 -> 1341.252 | F40: =SUM(G40:H40) -> 7129.01 | G40: ='[2]Thu '!E28 -> 7129.01 | H40: ='[2]Thu '!F28 -> 0 | I40: ='[2]Thu '!G28 -> 21.384 | J40: =SUM(K40:N40) -> 8491.646 | K40: =[2]TPTN!$AB$16 -> 8323.098 | M40: =[2]TPTN!$AB$31 -> 168.548
B41: Quan Triều | C41: 4215 | D41: =E41+F41+I41 -> 9033.232 | E41: ='[2]Thu '!D29 -> 1411.6 | F41: =SUM(G41:H41) -> 7621.632 | G41: ='[2]Thu '!E29 -> 7621.632 | H41: ='[2]Thu '!F29 -> 0 | I41: ='[2]Thu '!G29 -> 0 | J41: =SUM(K41:N41) -> 9033.232 | K41: =[2]TPTN!$AC$16 -> 8854.184 | M41: =[2]TPTN!$AC$31 -> 179.048
...

Sheet 34. CHI NS CẤP TỈNH
A1: Biểu mẫu số 34
A2: DỰ TOÁN CHI NGÂN SÁCH CẤP TỈNH THEO LĨNH VỰC NĂM 2025
A4: Đơn vị: Triệu đồng
A5: STT | B5: Nội dung | C5: Thái Nguyên
A6: A | B6: B | C6: 1
B7: TỔNG CHI NSĐP | C7: =C8+C9 -> #REF! | D7: =#REF! -> #REF!
A8: A | B8: CHI BỔ SUNG CHO NGÂN SÁCH CẤP DƯỚI (1) | C8: =#REF!+#REF! -> #REF! | D8: =C7-D7 -> #REF!
A9: B | B9: CHI NGÂN SÁCH CẤP TỈNH (HUYỆN, XÃ) THEO LĨNH VỰC | C9: =C10+C27+C40+C41+C42+C43 -> #REF!
A10: I | B10: Chi đầu tư phát triển (2) | C10: =C11+C26 -> #REF!
A11: 1 | B11: Chi đầu tư cho các dự án | C11: =#REF!+#REF!+#REF!+#REF! -> #REF!
A12: - | B12: Chi giáo dục - đào tạo và dạy nghề
A13: - | B13: Chi khoa học và công nghệ
A14: - | B14: Chi quốc phòng
A15: - | B15: Chi an ninh và trật tự an toàn xã hội
A16: - | B16: Chi y tế, dân số và gia đình
A17: - | B17: Chi văn hóa thông tin
A18: - | B18: Chi phát thanh, truyền hình, thông tấn
A19: - | B19: Chi thể dục thể thao
A20: - | B20: Chi bảo vệ môi trường
A21: - | B21: Chi các hoạt động kinh tế
A22: - | B22: Chi hoạt động của cơ quan quản lý nhà nước, đảng, đoàn thể
A23: - | B23: Chi bảo đảm xã hội
A24: - | B24: Chi đầu tư khác
A25: 2 | B25: Chi đầu tư và hỗ trợ vốn cho các doanh nghiệp cung cấp sản phẩm, dịch vụ công ích do Nhà nước đặt hàng, các tổ chức kinh tế,
A26: 3 | B26: Chi đầu tư phát triển khác | C26: =#REF! -> #REF!
A27: II | B27: Chi thường xuyên | C27: =SUM(C28:C39) -> #REF!
A28: - | B28: Chi sự nghiệp giáo dục đào tạo và dạy nghề | C28: =#REF! -> #REF!
A29: - | B29: Chi sự nghiệp y tế, dân số và gia đình | C29: =#REF! -> #REF!
A30: - | B30: Chi sự nghiệp khoa học và công nghệ | C30: =#REF! -> #REF!
A31: - | B31: Chi sự nghiệp văn hoá thông tin, thể dục thể thao | C31: =#REF! -> #REF!
A32: - | B32: Chi sự nghiệp phát thanh truyền hình | C32: =#REF! -> #REF!
A33: - | B33: Chi đảm bảo xã hội | C33: =#REF! -> #REF!
A34: - | B34: Sự nghiệp kinh tế | C34: =#REF! -> #REF!
A35: - | B35: Chi quản lý hành chính | C35: =#REF! -> #REF!
A36: - | B36: Chi sự nghiệp bảo vệ môi trường | C36: =#REF! -> #REF!
A37: - | B37: Chi quốc phòng an ninh địa phương | C37: =#REF! -> #REF!
A38: - | B38: Chi khác của ngân sách | C38: =#REF! -> #REF!
A39: - | B39: Tiết kiệm 10% 7 tháng cuối năm | C39: =#REF! -> #REF!
... A43: VI | B43: Chi tạo nguồn, điều chỉnh tiền lương | C43: =#REF! -> #REF!
A44: C | B44: CHI CHUYỂN NGUỒN SANG NĂM SAU

Sheet 37.01 ĐP
R1: Biểu mẫu số 37.2 NSĐP
A2: DỰ TOÁN CHI THƯỜNG XUYÊN CỦA NGÂN SÁCH CẤP TỈNH CHO TỪNG CƠ QUAN, TỔ CHỨC THEO LĨNH VỰC NĂM 2025
A3: (Dùng cho ngân sách các cấp chính quyền địa phương)
A4: (Kèm theo Công văn số /STC-HCSN ngày /6/2025 của Sở Tài chính)
R6: Đơn vị: Triệu đồng
A7: STT | B7: =E10+'37.02 TW'!E10 -> 5960899.9 | C7: Tổng số chi ngân sách khối tỉnh | D7: Trừ tiết kiệm 10% chi thường xuyên | E7: Số được chi từ nguồn ngân sách nhà nước | F7: Chi giáo dục - đào tạo và dạy nghề | G7: Chi khoa học và công nghệ | H7: Chi quốc phòng | I7: Chi an ninh và trật tự an toàn xã hội | J7: Chi y tế, dân số và gia đình | K7: Chi văn hóa thông tin | L7: Chi phát thanh, truyền hình, thông tấn | M7: Chi thể dục thể thao | N7: Chi bảo vệ môi trường | O7: Chi các hoạt động kinh tế | P7: Trong đó | R7: Chi hoạt động của cơ quan quản lý nhà nước, đảng, đoàn thể | S7: Chi bảo đảm xã hội | T7: Chi thường xuyên khác | U7: Kinh phí chuyển thanh tra | V7: Nhiệm vụ khác | W7: chuyển về xã Bắc kạn | X7: KP huyện chuyển nv lên tỉnh Bắc Kạn | Y7: TTXTĐT Bắc Kạn chuyển về 3 Sở | Z7: Điều chỉnh kinh phí luân chuyển cán bộ các ngành | AA7: TỔNG | AC7: 2718461
P8: Chi giao thông | Q8: Chi nông nghiệp, lâm nghiệp, thủy lợi, thủy sản | AC8: 2718279 | AD8: Đối ứng | AE8: BSCMT
A9: A | B9: B | E9: 1 | F9: 2 | G9: 3 | H9: 4 | I9: 5 | J9: 6 | K9: 7 | L9: 8 | M9: 9 | N9: 10 | O9: 11 | P9: 12 | Q9: 13 | R9: 14 | S9: 15 | T9: 16 | AI9: =AI11-AI10 -> 3175886
B10: TỔNG SỐ | C10: =C11+C12 -> 5647089.2 | D10: =D11+D12 -> 44502 | E10: =E11+E12 -> 5602587.2 | F10: =F11+F12 -> 1228144 | G10: =G11+G12 -> 63031 | H10: =H11+H12 -> 112788 | I10: =I11+I12 -> 64294 | J10: =J11+J12 -> 1578406 | ... Z10: =Z11+Z12 -> 371 | AC10: =AC11-AC12 -> 0 | AI10: =AB7+AB8 -> 0
